Workbook
Name ProjectName: 'Project Info'!$C$3
Name GCName: 'Project Info'!$C$6
Name FringeBurden: 'Project Info'!$C$21
Name OTPremium: 'Project Info'!$C$22
Name LaborOH: 'Project Info'!$C$23
Name LaborProfit: 'Project Info'!$C$24
Name MaterialMarkup: 'Project Info'!$C$25
Name EquipRentedMarkup: 'Project Info'!$C$26
Name EquipOwnedMarkup: 'Project Info'!$C$27
Name SubMarkup: 'Project Info'!$C$28
Name Contingency: 'Project Info'!$C$29
Name BondPct: 'Project Info'!$C$30
Name ProjectOH: 'Project Info'!$C$31
Name ProjectProfit: 'Project Info'!$C$32
Name MaxHeight: 'Project Info'!$C$35
Name HeightPremium: 'Project Info'!$C$36
Name AfterHours: 'Project Info'!$C$37
Name DistanceFromShop: 'Project Info'!$C$38
Name IsAESS: 'Project Info'!$C$39
Name IsComplex: 'Project Info'!$C$40
Name AccessConstrained: 'Project Info'!$C$41
Name IsPrevailingWage: 'Project Info'!$C$15
Name WageRates: 'Wage Rates'!$A$5:$G$22
Name EquipRates: 'Equipment Rates'!$A$5:$H$22
Name TakeoffTable: 'Material Takeoff'!$A$5:$I$45
Name TotalPremiumPct: 'Premiums & Conditions'!$D$17

Sheet Instructions
A1: STEEL ERECTION BID ESTIMATOR — Instructions
A3: WHAT THIS WORKBOOK IS
A4: A tonnage-based bid estimator for a structural-steel erection subcontractor. Output is a final bid number broken down by CSI division and section, suitable for submitting on a commercial bid form (use the Bid Package & Prequalification template from the Universal Sub Suite for the wrapper).
A6: WORKFLOW (TYPICAL BID DAY)
A7: 1. Open the bid documents and identify the structural drawings (S-series sheets) + project manual (Division 05 specifications).
A8: 2. Project Info: fill in the project, GC, delivery method, schedule, location, prevailing-wage flag, and contract-type assumptions. These drive every other tab.
A9: 3. Wage Rates: review the defaults against the locality + project labor regime. On Davis-Bacon or state-prevailing-wage projects, REPLACE the defaults with the controlling wage determination (see Certified Payroll Tracker for parallel workflow).
A10: 4. Equipment Rates: replace defaults with quotes from your crane vendor for the project tonnage + reach + pick weight. The 200T crawler default is a sample; bigger projects need bigger cranes.
A11: 5. Material Takeoff: enter the tonnage / sqft / count by CSI section. The takeoff usually comes from a quantity surveyor's report, a fabricator's takeoff (if you bid as erector-only), or your own takeoff from the structural drawings.
A12: 6. Labor Estimate: apply productivity rates (hrs/ton) by member class and crew composition. Industry-average productivity rates are pre-loaded; tighten or relax based on project access, complexity, weather window, etc.
A13: 7. Equipment Estimate: estimate crane-days and support-equipment days by phase.
A14: 8. Subcontract Estimate: if any scope is subbed (high-strength bolting, certified welding, fireproofing, painting), price as lump-sum or unit-price.
... A50: This estimator is calibrated for FIELD ERECTION only. Fabrication shop work is OUT OF SCOPE — if your firm fabricates AND erects, use a separate fabrication-shop estimator (different rate structure, different productivity, different material handling).

Sheet Project Info
B1: PROJECT INFORMATION — Steel Erection Bid
B3: Project Name
B4: Project Address
B5: Owner
B6: General Contractor (bidding to)
B7: Bid Due Date
B8: Project Type | C8: Commercial — New Construction
B9: Delivery Method | C9: Design-Bid-Build
B10: Construction Schedule (months) | C10: 0
B11: Anticipated Steel Erection Start
B12: Anticipated Steel Erection Duration (weeks) | C12: 0
B14: LABOR REGIME
B15: Davis-Bacon / Prevailing Wage Project? | C15: No
B16: Wage Determination ID (if prevailing wage)
B17: Union Project? | C17: No
B18: Project State (controls workers' comp + EMR application)
B20: BID ECONOMICS
B21: Fringe Burden % (on bare wage) | C21: 0.4
B22: OT Premium Multiplier | C22: 1.5
B23: Labor Overhead % | C23: 0.15
B24: Labor Profit % | C24: 0.1
B25: Material Markup % | C25: 0.1
B26: Equipment Markup % (rented) | C26: 0.08
B27: Equipment Markup % (owned) | C27: 0.1
B28: Subcontract Markup % | C28: 0.07
B29: Project Contingency % | C29: 0.04
B30: Bond % of Bid | C30: 0.012
B31: Project-Level Overhead % | C31: 0.13
B32: Profit % | C32: 0.1
B34: KEY PROJECT ATTRIBUTES
B35: Maximum Working Height (ft) | C35: 0
B36: Heights >50ft Premium Trigger? | C36: No
B37: After-Hours / Weekend Work Required? | C37: No
B38: Distance from Shop (miles) | C38: 0
B39: AESS (Architecturally Exposed Steel)? | C39: No
B40: Complex Geometry (curved, slanted, offsets)? | C40: No
B41: Site Access Constraints (urban, occupied, phased)? | C41: No
B43: PRINCIPAL / BIDDER OF RECORD
B44: Estimator
B45: Project Executive (Sub)
...

Sheet Wage Rates
A1: WAGE RATES — Ironworker Classifications
A2: Bare wage = pre-burden hourly rate. Burdened = bare × (1 + FringeBurden). Billed = burdened × (1 + LaborOH) × (1 + LaborProfit). On prevailing-wage / Davis-Bacon projects, replace bare wage with the wage determination base rate; fringe is paid in cash or to a bona-fide plan.
A4: Classification | B4: Bare Wage ($/hr) | C4: OT Multiplier | D4: Burdened ST ($/hr) | E4: Burdened OT ($/hr) | F4: Billed ST ($/hr) | G4: Billed OT ($/hr) | H4: Notes
A5: Foreman / Working Foreman | B5: 58 | C5: 1.5 | D5: =B5*(1+FringeBurden) | E5: =IF(IsPrevailingWage="Yes",(B5*C5)+(B5*FringeBurden),B5*C5*(1+FringeBurden)) | F5: =D5*(1+LaborOH)*(1+LaborProfit) | G5: =E5*(1+LaborOH)*(1+LaborProfit)
A6: Journeyman Ironworker — Structural | B6: 46 | C6: 1.5 | D6: =B6*(1+FringeBurden) | E6: =IF(IsPrevailingWage="Yes",(B6*C6)+(B6*FringeBurden),B6*C6*(1+FringeBurden)) | F6: =D6*(1+LaborOH)*(1+LaborProfit) | G6: =E6*(1+LaborOH)*(1+LaborProfit)
A7: Journeyman Ironworker — Connector | B7: 48 | C7: 1.5 | D7: =B7*(1+FringeBurden) | E7: =IF(IsPrevailingWage="Yes",(B7*C7)+(B7*FringeBurden),B7*C7*(1+FringeBurden)) | F7: =D7*(1+LaborOH)*(1+LaborProfit) | G7: =E7*(1+LaborOH)*(1+LaborProfit)
A8: Journeyman Ironworker — Welder (Certified) | B8: 52 | C8: 1.5 | D8: =B8*(1+FringeBurden) | E8: =IF(IsPrevailingWage="Yes",(B8*C8)+(B8*FringeBurden),B8*C8*(1+FringeBurden)) | F8: =D8*(1+LaborOH)*(1+LaborProfit) | G8: =E8*(1+LaborOH)*(1+LaborProfit)
A9: Apprentice Ironworker — Year 4 | B9: 36 | C9: 1.5 | D9: =B9*(1+FringeBurden) | E9: =IF(IsPrevailingWage="Yes",(B9*C9)+(B9*FringeBurden),B9*C9*(1+FringeBurden)) | F9: =D9*(1+LaborOH)*(1+LaborProfit) | G9: =E9*(1+LaborOH)*(1+LaborProfit)
A10: Apprentice Ironworker — Year 3 | B10: 32 | C10: 1.5 | D10: =B10*(1+FringeBurden) | E10: =IF(IsPrevailingWage="Yes",(B10*C10)+(B10*FringeBurden),B10*C10*(1+FringeBurden)) | F10: =D10*(1+LaborOH)*(1+LaborProfit) | G10: =E10*(1+LaborOH)*(1+LaborProfit)
A11: Apprentice Ironworker — Year 2 | B11: 28 | C11: 1.5 | D11: =B11*(1+FringeBurden) | E11: =IF(IsPrevailingWage="Yes",(B11*C11)+(B11*FringeBurden),B11*C11*(1+FringeBurden)) | F11: =D11*(1+LaborOH)*(1+LaborProfit) | G11: =E11*(1+LaborOH)*(1+LaborProfit)
A12: Apprentice Ironworker — Year 1 | B12: 24 | C12: 1.5 | D12: =B12*(1+FringeBurden) | E12: =IF(IsPrevailingWage="Yes",(B12*C12)+(B12*FringeBurden),B12*C12*(1+FringeBurden)) | F12: =D12*(1+LaborOH)*(1+LaborProfit) | G12: =E12*(1+LaborOH)*(1+LaborProfit)
A13: Crane Operator | B13: 54 | C13: 1.5 | D13: =B13*(1+FringeBurden) | E13: =IF(IsPrevailingWage="Yes",(B13*C13)+(B13*FringeBurden),B13*C13*(1+FringeBurden)) | F13: =D13*(1+LaborOH)*(1+LaborProfit) | G13: =E13*(1+LaborOH)*(1+LaborProfit)
A14: Signal Person / Rigger | B14: 44 | C14: 1.5 | D14: =B14*(1+FringeBurden) | E14: =IF(IsPrevailingWage="Yes",(B14*C14)+(B14*FringeBurden),B14*C14*(1+FringeBurden)) | F14: =D14*(1+LaborOH)*(1+LaborProfit) | G14: =E14*(1+LaborOH)*(1+LaborProfit)
A15: Decker / Bolter | B15: 42 | C15: 1.5 | D15: =B15*(1+FringeBurden) | E15: =IF(IsPrevailingWage="Yes",(B15*C15)+(B15*FringeBurden),B15*C15*(1+FringeBurden)) | F15: =D15*(1+LaborOH)*(1+LaborProfit) | G15: =E15*(1+LaborOH)*(1+LaborProfit)
A16: Detailer (field) | B16: 50 | C16: 1 | D16: =B16*(1+FringeBurden) | E16: =IF(IsPrevailingWage="Yes",(B16*C16)+(B16*FringeBurden),B16*C16*(1+FringeBurden)) | F16: =D16*(1+LaborOH)*(1+LaborProfit) | G16: =E16*(1+LaborOH)*(1+LaborProfit)
A17: Field Engineer / Surveyor | B17: 56 | C17: 1 | D17: =B17*(1+FringeBurden) | E17: =IF(IsPrevailingWage="Yes",(B17*C17)+(B17*FringeBurden),B17*C17*(1+FringeBurden)) | F17: =D17*(1+LaborOH)*(1+LaborProfit) | G17: =E17*(1+LaborOH)*(1+LaborProfit)

Sheet Equipment Rates
A1: EQUIPMENT RATES
A2: Owned equipment: bare cost + internal markup. Rented: rental rate + small markup for handling. For project-specific bids, replace rental defaults with actual quotes from your crane vendor.
A4: Equipment | B4: Owned / Rented | C4: Hourly Rate ($) | D4: Daily Rate ($) | E4: Weekly Rate ($) | F4: Markup % | G4: Billed Daily ($) | H4: Billed Weekly ($) | I4: Notes
A5: Crawler crane — 80T | B5: Rented | C5: 185 | D5: 1850 | E5: 7400 | F5: =IF(B5="Owned",EquipOwnedMarkup,EquipRentedMarkup) | G5: =D5*(1+F5) | H5: =E5*(1+F5)
A6: Crawler crane — 110T | B6: Rented | C6: 235 | D6: 2350 | E6: 9400 | F6: =IF(B6="Owned",EquipOwnedMarkup,EquipRentedMarkup) | G6: =D6*(1+F6) | H6: =E6*(1+F6)
A7: Crawler crane — 150T | B7: Rented | C7: 310 | D7: 3100 | E7: 12400 | F7: =IF(B7="Owned",EquipOwnedMarkup,EquipRentedMarkup) | G7: =D7*(1+F7) | H7: =E7*(1+F7)
A8: Crawler crane — 200T | B8: Rented | C8: 395 | D8: 3950 | E8: 15800 | F8: =IF(B8="Owned",EquipOwnedMarkup,EquipRentedMarkup) | G8: =D8*(1+F8) | H8: =E8*(1+F8)
A9: Truck-mounted crane — 50T (RT) | B9: Rented | C9: 165 | D9: 1650 | E9: 6600 | F9: =IF(B9="Owned",EquipOwnedMarkup,EquipRentedMarkup) | G9: =D9*(1+F9) | H9: =E9*(1+F9)
A10: Truck-mounted crane — 80T (RT) | B10: Rented | C10: 220 | D10: 2200 | E10: 8800 | F10: =IF(B10="Owned",EquipOwnedMarkup,EquipRentedMarkup) | G10: =D10*(1+F10) | H10: =E10*(1+F10)
A11: Boom truck — 18T (carrydeck) | B11: Owned | C11: 95 | D11: 950 | E11: 3800 | F11: =IF(B11="Owned",EquipOwnedMarkup,EquipRentedMarkup) | G11: =D11*(1+F11) | H11: =E11*(1+F11)
A12: Telehandler / forklift | B12: Owned | C12: 72 | D12: 720 | E12: 2880 | F12: =IF(B12="Owned",EquipOwnedMarkup,EquipRentedMarkup) | G12: =D12*(1+F12) | H12: =E12*(1+F12)
A13: Aerial lift — scissor 26'-32' | B13: Rented | C13: 48 | D13: 480 | E13: 1920 | F13: =IF(B13="Owned",EquipOwnedMarkup,EquipRentedMarkup) | G13: =D13*(1+F13) | H13: =E13*(1+F13)
A14: Aerial lift — boom 60'-85' | B14: Rented | C14: 98 | D14: 980 | E14: 3920 | F14: =IF(B14="Owned",EquipOwnedMarkup,EquipRentedMarkup) | G14: =D14*(1+F14) | H14: =E14*(1+F14)
A15: Engine-drive welder (lincoln/miller) | B15: Owned | C15: 18 | D15: 180 | E15: 720 | F15: =IF(B15="Owned",EquipOwnedMarkup,EquipRentedMarkup) | G15: =D15*(1+F15) | H15: =E15*(1+F15)
A16: Air compressor — 185 cfm | B16: Owned | C16: 14 | D16: 140 | E16: 560 | F16: =IF(B16="Owned",EquipOwnedMarkup,EquipRentedMarkup) | G16: =D16*(1+F16) | H16: =E16*(1+F16)
A17: Generator — 25 kW | B17: Owned | C17: 12 | D17: 120 | E17: 480 | F17: =IF(B17="Owned",EquipOwnedMarkup,EquipRentedMarkup) | G17: =D17*(1+F17) | H17: =E17*(1+F17)

Sheet Material Takeoff
A1: MATERIAL TAKEOFF — CSI-Coded
A2: Enter one row per CSI-coded material/system. UOM examples: TON (structural steel), EA (joists), SF (decking), LF (railings), LB (bolts), GAL (paint). Materials supplied by erector — if the fabricator supplies material direct, exclude from this tab and note in Assumptions.
A4: Line # | B4: CSI Section | C4: Description | D4: UOM | E4: Quantity | F4: Unit Cost ($) | G4: Material Subtotal ($) | H4: Markup % | I4: Material Total ($) | J4: Notes
A5: =IF(C5="","",ROW()-4) | B5: 05 12 23 | C5: Structural Steel — Wide Flange (W shapes) | D5: TON | G5: =IFERROR(E5*F5,0) | H5: =MaterialMarkup | I5: =IFERROR(G5*(1+H5),0)
A6: =IF(C6="","",ROW()-4) | B6: 05 12 23 | C6: Structural Steel — HSS / Pipe | D6: TON | G6: =IFERROR(E6*F6,0) | H6: =MaterialMarkup | I6: =IFERROR(G6*(1+H6),0)
A7: =IF(C7="","",ROW()-4) | B7: 05 12 23 | C7: Structural Steel — Channels / Angles / MC | D7: TON | G7: =IFERROR(E7*F7,0) | H7: =MaterialMarkup | I7: =IFERROR(G7*(1+H7),0)
A8: =IF(C8="","",ROW()-4) | B8: 05 12 23 | C8: Structural Steel — Plate / Bent Plate | D8: TON | G8: =IFERROR(E8*F8,0) | H8: =MaterialMarkup | I8: =IFERROR(G8*(1+H8),0)
A9: =IF(C9="","",ROW()-4) | B9: 05 12 33 | C9: AESS — Architecturally Exposed Steel (premium) | D9: TON | G9: =IFERROR(E9*F9,0) | H9: =MaterialMarkup | I9: =IFERROR(G9*(1+H9),0)
A10: =IF(C10="","",ROW()-4) | B10: 05 12 23 | C10: High-Strength Bolts — A325 (3/4" ASTM F3125) | D10: EA | G10: =IFERROR(E10*F10,0) | H10: =MaterialMarkup | I10: =IFERROR(G10*(1+H10),0)
A11: =IF(C11="","",ROW()-4) | B11: 05 12 23 | C11: High-Strength Bolts — A325 (7/8" ASTM F3125) | D11: EA | G11: =IFERROR(E11*F11,0) | H11: =MaterialMarkup | I11: =IFERROR(G11*(1+H11),0)
A12: =IF(C12="","",ROW()-4) | B12: 05 12 23 | C12: High-Strength Bolts — A490 (1" ASTM F3125) | D12: EA | G12: =IFERROR(E12*F12,0) | H12: =MaterialMarkup | I12: =IFERROR(G12*(1+H12),0)
A13: =IF(C13="","",ROW()-4) | B13: 05 12 23 | C13: Tension-Control Bolts — F1852 / F2280 | D13: EA | G13: =IFERROR(E13*F13,0) | H13: =MaterialMarkup | I13: =IFERROR(G13*(1+H13),0)
A14: =IF(C14="","",ROW()-4) | B14: 05 12 23 | C14: Anchor Rods — F1554 Grade 36 | D14: EA | G14: =IFERROR(E14*F14,0) | H14: =MaterialMarkup | I14: =IFERROR(G14*(1+H14),0)
A15: =IF(C15="","",ROW()-4) | B15: 05 21 19 | C15: Open-Web Steel Joists — K-Series | D15: EA | G15: =IFERROR(E15*F15,0) | H15: =MaterialMarkup | I15: =IFERROR(G15*(1+H15),0)
A16: =IF(C16="","",ROW()-4) | B16: 05 21 19 | C16: Open-Web Steel Joists — LH-Series | D16: EA | G16: =IFERROR(E16*F16,0) | H16: =MaterialMarkup | I16: =IFERROR(G16*(1+H16),0)
... A31: =IF(C31="","",ROW()-4) | B31: 09 91 00 | C31: Touch-Up Primer (welds + abrasions) | D31: GAL | G31: =IFERROR(E31*F31,0) | H31: =MaterialMarkup | I31: =IFERROR(G31*(1+H31),0)
A32: =IF(C32="","",ROW()-4) | G32: =IFERROR(E32*F32,0) | H32: =MaterialMarkup | I32: =IFERROR(G32*(1+H32),0)
A33: =IF(C33="","",ROW()-4) | G33: =IFERROR(E33*F33,0) | H33: =MaterialMarkup | I33: =IFERROR(G33*(1+H33),0)
A34: =IF(C34="","",ROW()-4) | G34: =IFERROR(E34*F34,0) | H34: =MaterialMarkup | I34: =IFERROR(G34*(1+H34),0)
A35: =IF(C35="","",ROW()-4) | G35: =IFERROR(E35*F35,0) | H35: =MaterialMarkup | I35: =IFERROR(G35*(1+H35),0)
C36: MATERIAL TOTAL | G36: =SUMIFS(G5:G35,C5:C35,"<>") | I36: =SUMIFS(I5:I35,C5:C35,"<>")

Sheet Labor Estimate
A1: LABOR ESTIMATE — Productivity × Crew × Rate
A2: Productivity = crew-hours per unit of work (e.g., 3.50 crew-hrs/ton = a 5-person crew working an 8-hour day erects roughly 11.5 tons/day). Pull quantities from Material Takeoff. Avg Crew Rate is the loaded (burdened + marked-up) blended hourly rate across the crew composition.
A3: ⚠ CALIBRATE AGAINST YOUR LAST 3 COMPLETED JOBS BEFORE TRUSTING THESE NUMBERS. Defaults are commercial-South non-union industry averages. Union work, cold climates, AESS, or congested sites typically run 20-40% slower.
A5: Activity | B5: CSI Section | C5: Quantity | D5: UOM | E5: Productivity (hrs/UOM) | F5: Crew Composition (#) | G5: Total Labor Hours | H5: Avg Crew Rate ($/hr) | I5: Labor Total ($) | J5: Notes
A6: Erect structural steel — typical | B6: 05 12 23 | D6: TON | E6: 3.5 | F6: 5 | G6: =IFERROR(C6*E6,0) | H6: 46 | I6: =IFERROR(G6*H6*(1+FringeBurden)*(1+LaborOH)*(1+LaborProfit),0)
A7: Erect structural steel — AESS (premium) | B7: 05 12 33 | D7: TON | E7: 6.5 | F7: 5 | G7: =IFERROR(C7*E7,0) | H7: 46 | I7: =IFERROR(G7*H7*(1+FringeBurden)*(1+LaborOH)*(1+LaborProfit),0)
A8: Erect open-web joists | B8: 05 21 19 | D8: EA | E8: 0.4 | F8: 4 | G8: =IFERROR(C8*E8,0) | H8: 44 | I8: =IFERROR(G8*H8*(1+FringeBurden)*(1+LaborOH)*(1+LaborProfit),0)
A9: Erect joist girders | B9: 05 21 23 | D9: EA | E9: 1.5 | F9: 4 | G9: =IFERROR(C9*E9,0) | H9: 46 | I9: =IFERROR(G9*H9*(1+FringeBurden)*(1+LaborOH)*(1+LaborProfit),0)
A10: Install floor decking | B10: 05 31 13 | D10: SF | E10: 0.02 | F10: 4 | G10: =IFERROR(C10*E10,0) | H10: 42 | I10: =IFERROR(G10*H10*(1+FringeBurden)*(1+LaborOH)*(1+LaborProfit),0)
A11: Install roof decking | B11: 05 31 23 | D11: SF | E11: 0.018 | F11: 4 | G11: =IFERROR(C11*E11,0) | H11: 42 | I11: =IFERROR(G11*H11*(1+FringeBurden)*(1+LaborOH)*(1+LaborProfit),0)
A12: Install shear studs (Nelson-stud welding) | B12: 05 31 13 | D12: EA | E12: 0.08 | F12: 2 | G12: =IFERROR(C12*E12,0) | H12: 48 | I12: =IFERROR(G12*H12*(1+FringeBurden)*(1+LaborOH)*(1+LaborProfit),0)
A13: Set / shim embeds and base plates | B13: 05 12 23 | D13: EA | E13: 0.5 | F13: 2 | G13: =IFERROR(C13*E13,0) | H13: 44 | I13: =IFERROR(G13*H13*(1+FringeBurden)*(1+LaborOH)*(1+LaborProfit),0)
A14: Install misc metals (embeds, lintels) | B14: 05 50 00 | D14: EA | E14: 1 | F14: 2 | G14: =IFERROR(C14*E14,0) | H14: 44 | I14: =IFERROR(G14*H14*(1+FringeBurden)*(1+LaborOH)*(1+LaborProfit),0)
A15: Install metal pan stairs (per riser) | B15: 05 51 13 | D15: EA | E15: 0.6 | F15: 3 | G15: =IFERROR(C15*E15,0) | H15: 46 | I15: =IFERROR(G15*H15*(1+FringeBurden)*(1+LaborOH)*(1+LaborProfit),0)
A16: Install pipe railings | B16: 05 52 13 | D16: LF | E16: 0.3 | F16: 2 | G16: =IFERROR(C16*E16,0) | H16: 42 | I16: =IFERROR(G16*H16*(1+FringeBurden)*(1+LaborOH)*(1+LaborProfit),0)
A17: Bolt-up (high-strength, turn-of-nut) | B17: 05 12 23 | D17: EA | E17: 0.08 | F17: 2 | G17: =IFERROR(C17*E17,0) | H17: 42 | I17: =IFERROR(G17*H17*(1+FringeBurden)*(1+LaborOH)*(1+LaborProfit),0)
... A21: Final cleanup / demobilization | B21: 05 12 23 | D21: DAY | E21: 8 | F21: 4 | G21: =IFERROR(C21*E21,0) | H21: 42 | I21: =IFERROR(G21*H21*(1+FringeBurden)*(1+LaborOH)*(1+LaborProfit),0)
A22: LABOR TOTAL | G22: =SUM(G6:G21) | I22: =SUM(I6:I21)

Sheet Equipment Estimate
A1: EQUIPMENT ESTIMATE
A2: Days = total billable days on the project. Crane phase typically = structural steel + joists + girders + decking days. Some equipment (welder, generator) runs the full erection duration.
A4: Equipment | B4: Phase / Activity | C4: Days | D4: Daily Rate ($) | E4: Subtotal ($) | F4: Markup % | G4: Total ($) | H4: Notes
A5: Primary crane (e.g., 150T crawler) | B5: Steel + joists + decking | D5: 3100 | E5: =IFERROR(C5*D5,0) | F5: =EquipRentedMarkup | G5: =IFERROR(E5*(1+F5),0)
A6: Secondary crane (e.g., 80T) | B6: Misc lifts / overflow | D6: 1850 | E6: =IFERROR(C6*D6,0) | F6: =EquipRentedMarkup | G6: =IFERROR(E6*(1+F6),0)
A7: Boom truck / carrydeck | B7: Bolt-up + misc | D7: 950 | E7: =IFERROR(C7*D7,0) | F7: =EquipRentedMarkup | G7: =IFERROR(E7*(1+F7),0)
A8: Aerial lift — boom 60-85' | B8: Connection / welding | D8: 980 | E8: =IFERROR(C8*D8,0) | F8: =EquipRentedMarkup | G8: =IFERROR(E8*(1+F8),0)
A9: Aerial lift — scissor | B9: Decking / detailing | D9: 480 | E9: =IFERROR(C9*D9,0) | F9: =EquipRentedMarkup | G9: =IFERROR(E9*(1+F9),0)
A10: Engine-drive welder | B10: Field welding | D10: 180 | E10: =IFERROR(C10*D10,0) | F10: =EquipRentedMarkup | G10: =IFERROR(E10*(1+F10),0)
A11: Telehandler / forklift | B11: Material handling | D11: 720 | E11: =IFERROR(C11*D11,0) | F11: =EquipRentedMarkup | G11: =IFERROR(E11*(1+F11),0)
A12: Air compressor | B12: Bolting / impact | D12: 140 | E12: =IFERROR(C12*D12,0) | F12: =EquipRentedMarkup | G12: =IFERROR(E12*(1+F12),0)
A13: Generator | B13: Power for tools | D13: 120 | E13: =IFERROR(C13*D13,0) | F13: =EquipRentedMarkup | G13: =IFERROR(E13*(1+F13),0)
A14: Mobilization / demobilization (allowance) | B14: Each crane move | D14: 0 | E14: =IFERROR(C14*D14,0) | F14: =EquipRentedMarkup | G14: =IFERROR(E14*(1+F14),0)
D15: 0 | E15: =IFERROR(C15*D15,0) | F15: =EquipRentedMarkup | G15: =IFERROR(E15*(1+F15),0)
A16: EQUIPMENT TOTAL | E16: =SUM(E5:E15) | G16: =SUM(G5:G15)

Sheet Subcontract Estimate
A1: SUBCONTRACT ESTIMATE — Lower-Tier Work
A2: Scopes commonly subbed by a steel erector: high-strength bolting, certified welding, spray-applied fireproofing, painting/galvanizing touch-up, decking install (if not self-performed). Get firm quotes from the lower-tier sub before bid day; lump-sum or unit-price.
A4: Scope | B4: CSI Section | C4: Sub Quote ($) | D4: Markup % | E4: Total ($) | F4: Sub Name | G4: Notes
A5: High-strength bolting (TC bolts, calibrated wrench) | B5: 05 12 23 | D5: =SubMarkup | E5: =IFERROR(C5*(1+D5),0)
A6: Certified welding (AWS D1.1 structural) | B6: 05 12 23 | D6: =SubMarkup | E6: =IFERROR(C6*(1+D6),0)
A7: Spray-applied fireproofing (SFRM) | B7: 07 81 00 | D7: =SubMarkup | E7: =IFERROR(C7*(1+D7),0)
A8: Touch-up primer / paint | B8: 09 91 00 | D8: =SubMarkup | E8: =IFERROR(C8*(1+D8),0)
A9: Galvanizing repair (cold-galv compound) | B9: 05 12 23 | D9: =SubMarkup | E9: =IFERROR(C9*(1+D9),0)
A10: Decking install (if not self-performed) | B10: 05 31 13 | D10: =SubMarkup | E10: =IFERROR(C10*(1+D10),0)
A11: Bolt inspection (third-party) | B11: 05 12 23 | D11: =SubMarkup | E11: =IFERROR(C11*(1+D11),0)
A12: Welding inspection (third-party UT/MT/PT) | B12: 05 12 23 | D12: =SubMarkup | E12: =IFERROR(C12*(1+D12),0)
D13: =SubMarkup | E13: =IFERROR(C13*(1+D13),0)
D14: =SubMarkup | E14: =IFERROR(C14*(1+D14),0)
A15: SUBCONTRACT TOTAL | C15: =SUM(C5:C14) | E15: =SUM(E5:E14)

Sheet Premiums & Conditions
B1: PREMIUMS & CONDITIONS — Risk Adders
B2: Percentage adders applied to the base labor + equipment + subcontract subtotal. Use when a project attribute materially increases productivity loss, risk, or carrying cost.
B4: Condition | C4: Applies? | D4: Premium % | E4: Basis / Notes
B5: Working at heights >50 ft (OSHA 1926.760 fall protection) | C5: =HeightPremium | D5: 0.07 | E5: Productivity loss, equipment for fall protection
B6: After-hours / weekend / night work (shift premium) | C6: =AfterHours | D6: 0.15 | E6: 1.5× OT or shift differential
B7: Distance from shop >50 miles | C7: =IF(DistanceFromShop>50,"Yes","No") | D7: 0.04 | E7: Per-diem, travel time, equipment-move cost
B8: Architecturally Exposed Steel (AESS — Tier 2 or higher) | C8: =IsAESS | D8: 0.12 | E8: Slower productivity, higher tolerance, more handling
B9: Complex geometry (curved, slanted, twisted, offsets) | C9: =IsComplex | D9: 0.1 | E9: Slower placement, more shimming, more rework
B10: Constrained site (urban, occupied, phased, tight crane swing) | C10: =AccessConstrained | D10: 0.08 | E10: Slower productivity + more crane positions
B11: Winter weather (Nov-Mar in cold climates) | C11: No | D11: 0.06 | E11: Lost days, equipment heating, ice/snow removal
B12: Hurricane / wind contingency (coastal projects) | C12: No | D12: 0.03 | E12: Stoppage during named storms, anchor verification
B13: Davis-Bacon / state prevailing wage | C13: =IsPrevailingWage | D13: 0 | E13: Already captured in wage rates — informational
B14: Project-specific PPE (FR, arc-flash, special tie-off) | C14: No | D14: 0.01 | E14: PPE replacement frequency
D15: 0
D16: 0
B17: TOTAL PREMIUM % (applied to labor + equip + sub) | D17: =SUMPRODUCT((C5:C16="Yes")*D5:D16)

Sheet Bid Summary
B1: BID SUMMARY — Roll-Up to Final Bid
B2: Project: =ProjectName GC: =GCName
B4: DIRECT COST ROLL-UP
B5: Material (from Material Takeoff) | C5: ='Material Takeoff'!I36
B6: Labor (from Labor Estimate) | C6: ='Labor Estimate'!I22
B7: Equipment (from Equipment Estimate) | C7: ='Equipment Estimate'!G16
B8: Subcontract (from Subcontract Estimate) | C8: ='Subcontract Estimate'!E15
B9: DIRECT COST SUBTOTAL | C9: =SUM(C5:C8)
B11: Premium (heights, after-hours, distance, AESS, etc.) | C11: =C9*TotalPremiumPct | D11: =TotalPremiumPct
B12: COST OF WORK SUBTOTAL | C12: =C9+C11
B13: Contingency | C13: =C12*Contingency | D13: =Contingency
B14: Project Overhead (general conditions, supervision) | C14: =C12*ProjectOH | D14: =ProjectOH
B15: Profit | C15: =C12*ProjectProfit | D15: =ProjectProfit
B16: BID BEFORE BOND | C16: =C12+C13+C14+C15
B17: Performance + Payment Bond | C17: =C16*BondPct/(1-BondPct) | D17: =BondPct | E17: Of final bid
B19: FINAL BID NUMBER | C19: =C16+C17
B22: SANITY CHECKS
B23: $/Ton (final bid / total structural tons) | C23: =IFERROR(C19/(SUMIFS('Material Takeoff'!E:E,'Material Takeoff'!B:B,"05 12 23",'Material Takeoff'!D:D,"TON")+SUMIFS('Material Takeoff'!E:E,'Material Takeoff'!B:B,"05 12 33",'Material Takeoff'!D:D,"TON")),0)
B24: $/SF Decking (subcontract + decking labor) | C24: =IFERROR((SUMIFS('Labor Estimate'!I:I,'Labor Estimate'!B:B,"05 31 13")+SUMIFS('Labor Estimate'!I:I,'Labor Estimate'!B:B,"05 31 23"))/(SUMIFS('Material Takeoff'!E:E,'Material Takeoff'!B:B,"05 31 13",'Material Takeoff'!D:D,"SF")+SUMIFS('Material Takeoff'!E:E,'Material Takeoff'!B:B,"05 31 23",'Material Takeoff'!D:D,"SF")),0)
B25: Labor % of final bid (sanity: typically 25-45%) | C25: =IFERROR('Labor Estimate'!I22/C19,0)
B26: Equipment % of final bid (sanity: typically 8-18%) | C26: =IFERROR('Equipment Estimate'!G16/C19,0)
B27: Markup % effective (above raw direct cost) | C27: =IFERROR((C19-C9)/C9,0)
B30: CSI DIVISION ROLL-UP (for Sub Schedule of Values)
B31: CSI Division | C31: Material ($) | D31: Labor ($) | E31: Total ($)
B32: 03 — Cast-in-Place Concrete (embeds cross-ref) | C32: =SUMPRODUCT((LEFT('Material Takeoff'!B5:B40,2)="03")*'Material Takeoff'!I5:I40) | D32: =SUMPRODUCT((LEFT('Labor Estimate'!B5:B25,2)="03")*'Labor Estimate'!I5:I25) | E32: =C32+D32
B33: 05 — Metals | C33: =SUMPRODUCT((LEFT('Material Takeoff'!B5:B40,2)="05")*'Material Takeoff'!I5:I40) | D33: =SUMPRODUCT((LEFT('Labor Estimate'!B5:B25,2)="05")*'Labor Estimate'!I5:I25) | E33: =C33+D33
B34: 07 — Thermal & Moisture (fireproofing cross-ref) | C34: =SUMPRODUCT((LEFT('Material Takeoff'!B5:B40,2)="07")*'Material Takeoff'!I5:I40) | D34: =SUMPRODUCT((LEFT('Labor Estimate'!B5:B25,2)="07")*'Labor Estimate'!I5:I25) | E34: =C34+D34
B35: 09 — Finishes (paint cross-ref) | C35: =SUMPRODUCT((LEFT('Material Takeoff'!B5:B40,2)="09")*'Material Takeoff'!I5:I40) | D35: =SUMPRODUCT((LEFT('Labor Estimate'!B5:B25,2)="09")*'Labor Estimate'!I5:I25) | E35: =C35+D35

Sheet CSI Reference
A1: CSI MasterFormat — Steel Erector Scope
A3: Section | B3: Title | C3: Scope Notes
A4: 05 12 23 | B4: Structural Steel Framing | C4: Primary structural steel members (W, HSS, C, L, MC shapes)
A5: 05 12 33 | B5: Architecturally Exposed Structural Steel (AESS) | C5: AESS tier finish steel — higher tolerance, more prep
A6: 05 21 19 | B6: Open-Web Steel Joists | C6: K-series, LH-series, DLH-series joists
A7: 05 21 23 | B7: Joist Girders | C7: Long-span joist girders supporting joists
A8: 05 31 13 | B8: Steel Floor Decking | C8: Composite or non-composite floor deck (1.5VL, 2VL, 3VL, etc.)
A9: 05 31 23 | B9: Steel Roof Decking | C9: Roof deck (1.5B, 2B, 3B, 1.5BR, etc.)
A10: 05 31 33 | B10: Steel Form Decking | C10: Permanent metal form decking
A11: 05 41 00 | B11: Structural Metal Stud Framing | C11: Load-bearing metal stud framing (rare for erector)
A12: 05 50 00 | B12: Metal Fabrications | C12: Miscellaneous metals — railings, ladders, embed plates
A13: 05 51 13 | B13: Metal Pan Stairs | C13: Metal pan stairs installed by erector
A14: 05 51 33 | B14: Metal Ladders | C14: Caged/uncaged metal ladders
... A23: 33 16 00 | B23: Water Utility Storage Tanks (Steel) | C23: Bolted/welded steel water tanks
