Workbook
Name WageClassifications: 'Wage Rates'!$A$4:$A$10
Name WageLoadedRates: 'Wage Rates'!$F$4:$F$10

Sheet Instructions
A1: PLUMBING BID ESTIMATOR — INSTRUCTIONS
A4: PURPOSE
A5: Production estimating tool for commercial plumbing contractors. Fixture- and
A6: linear-foot-based with PHCC/MCAA-style labor units. CSI Division 22 primary
A7: with cross-references to Division 23 (mechanical), 31 (earthwork), and 33
A8: (utilities). Output rolls up by CSI division so the bid integrates cleanly into
A9: the GC's job-cost accounting and into your monthly billing on the Universal
A10: Sub Suite's Sub_Schedule_of_Values.xlsx.
A12: WORKFLOW
A13: 1. Project Info — fill in every blue-filled field. The cells you leave blank
A14: show up as warnings on the Bid Summary tab.
A15: 2. Wage Rates — set hourly base + fringe + OT premium for each classification.
... A56: ContrPro Complete Tier · Plumbing Trade Pack

Sheet Bid Summary
A1: BID SUMMARY — Plumbing Trade Pack
B3: Material total (incl. tax) | C3: ='Material Takeoff'!$F$81
B4: Labor total | C4: ='Labor Estimate'!$H$50
B5: Equipment total | C5: ='Equipment'!$F$22
B6: Subcontract total | C6: ='Subcontract'!$E$15
B7: Premiums $ (sum of applies-Y) | C7: ='Premiums'!$D$19
B8: Direct cost subtotal | C8: =SUM(C3:C7)
B9: Premium % applied to direct cost | C9: ='Premiums'!$D$20
B10: Premium % adder $ | C10: =C8*C9
B11: Direct cost with premium % | C11: =C8+C10
B12: Contingency % | C12: 0.05
B13: Contingency $ | C13: =C11*C12
B14: Direct + contingency | C14: =C11+C13
B15: Overhead % | C15: 0.1
B16: Overhead $ | C16: =C14*C15
B17: Profit % | C17: 0.1
B18: Profit $ | C18: =(C14+C16)*C17
B19: Bond % | C19: 0.012
B20: Bond $ | C20: =(C14+C16+C18)*C19
B21: Insurance / GL premium % | C21: 0.018
B22: Insurance $ | C22: =(C14+C16+C18)*C21
B23: FINAL BID | C23: =C14+C16+C18+C20+C22
B26: Premium % adders APPLY ON TOP of the direct-cost subtotal before contingency. Contingency, OH, and profit each compound on the running subtotal. Adjust OH and profit % to match your historical floor.
B29: CSI DIVISION ROLL-UP (informational)
B30: CSI Division | C30: Material $ | D30: Labor $
B31: 22 11 - Water Distribution | C31: =SUMPRODUCT((LEFT('Material Takeoff'!A4:A200,LEN("22 11"))="22 11")*'Material Takeoff'!F4:F200) | D31: =SUMPRODUCT((LEFT('Labor Estimate'!A4:A200,LEN("22 11"))="22 11")*'Labor Estimate'!H4:H200)
B32: 22 13 - Sanitary Sewerage | C32: =SUMPRODUCT((LEFT('Material Takeoff'!A4:A200,LEN("22 13"))="22 13")*'Material Takeoff'!F4:F200) | D32: =SUMPRODUCT((LEFT('Labor Estimate'!A4:A200,LEN("22 13"))="22 13")*'Labor Estimate'!H4:H200)
B33: 22 14 - Storm Drainage | C33: =SUMPRODUCT((LEFT('Material Takeoff'!A4:A200,LEN("22 14"))="22 14")*'Material Takeoff'!F4:F200) | D33: =SUMPRODUCT((LEFT('Labor Estimate'!A4:A200,LEN("22 14"))="22 14")*'Labor Estimate'!H4:H200)
B34: 22 33-35 - Water Heaters | C34: =SUMPRODUCT((LEFT('Material Takeoff'!A4:A200,LEN("22 3"))="22 3")*'Material Takeoff'!F4:F200) | D34: =SUMPRODUCT((LEFT('Labor Estimate'!A4:A200,LEN("22 3"))="22 3")*'Labor Estimate'!H4:H200)
B35: 22 42-45 - Plumbing Fixtures | C35: =SUMPRODUCT((LEFT('Material Takeoff'!A4:A200,LEN("22 4"))="22 4")*'Material Takeoff'!F4:F200) | D35: =SUMPRODUCT((LEFT('Labor Estimate'!A4:A200,LEN("22 4"))="22 4")*'Labor Estimate'!H4:H200)
B36: 22 60-67 - Gas + Specialty | C36: =SUMPRODUCT((LEFT('Material Takeoff'!A4:A200,LEN("22 6"))="22 6")*'Material Takeoff'!F4:F200) | D36: =SUMPRODUCT((LEFT('Labor Estimate'!A4:A200,LEN("22 6"))="22 6")*'Labor Estimate'!H4:H200)
B37: 22 05 - Common Work Results | C37: =SUMPRODUCT((LEFT('Material Takeoff'!A4:A200,LEN("22 05"))="22 05")*'Material Takeoff'!F4:F200) | D37: =SUMPRODUCT((LEFT('Labor Estimate'!A4:A200,LEN("22 05"))="22 05")*'Labor Estimate'!H4:H200)
B38: 22 07 - Insulation | C38: =SUMPRODUCT((LEFT('Material Takeoff'!A4:A200,LEN("22 07"))="22 07")*'Material Takeoff'!F4:F200) | D38: =SUMPRODUCT((LEFT('Labor Estimate'!A4:A200,LEN("22 07"))="22 07")*'Labor Estimate'!H4:H200)
B39: 22 08 - Test + Commissioning | C39: =SUMPRODUCT((LEFT('Material Takeoff'!A4:A200,LEN("22 08"))="22 08")*'Material Takeoff'!F4:F200) | D39: =SUMPRODUCT((LEFT('Labor Estimate'!A4:A200,LEN("22 08"))="22 08")*'Labor Estimate'!H4:H200)

Sheet Project Info
A1: PROJECT INFORMATION
A3: Project Name
A4: Project Address
A5: Owner
A6: General Contractor
A7: Architect / Engineer
A8: Bid Due Date
A9: Bid Reference / Number
A10: Project Type | B10: (New construction / Renovation / Tenant fit-out / Adaptive reuse)
A11: Building Use | B11: (Office / Retail / Healthcare / Education / Multi-family / Hospitality / Industrial / Mixed)
A12: Approx. Square Footage
A13: Stories
A14: Plumbing Fixture Count (est.)
A15: AHJ — Plumbing Inspector
A16: Applicable Plumbing Code | B16: (IPC 2024 / UPC 2024 / Local amendment)
A17: Estimator Name
A18: Estimator Phone
A19: Estimator Email
A20: Date Prepared
A21: Internal Bid Number
A22: Notes / Assumptions

Sheet Wage Rates
A1: WAGE RATES (calibrate to your market)
A3: Classification | B3: Base Rate ($/hr) | C3: Fringe ($/hr) | D3: Burden % (WC/GL/FICA) | E3: OT Premium (1.5×) | F3: Loaded Rate ($/hr)
A4: Plumbing Foreman | B4: 58 | C4: 18.5 | D4: 0.32 | E4: =B4*1.5 | F4: =(B4+C4)*(1+D4)
A5: Journeyman Plumber | B5: 48 | C5: 18.5 | D5: 0.32 | E5: =B5*1.5 | F5: =(B5+C5)*(1+D5)
A6: Apprentice (Yr 4) | B6: 38 | C6: 14 | D6: 0.32 | E6: =B6*1.5 | F6: =(B6+C6)*(1+D6)
A7: Apprentice (Yr 2) | B7: 28 | C7: 12 | D7: 0.32 | E7: =B7*1.5 | F7: =(B7+C7)*(1+D7)
A8: Laborer / Helper | B8: 22 | C8: 9 | D8: 0.32 | E8: =B8*1.5 | F8: =(B8+C8)*(1+D8)
A9: Service Tech | B9: 55 | C9: 18.5 | D9: 0.32 | E9: =B9*1.5 | F9: =(B9+C9)*(1+D9)
A10: Pipefitter (gas) | B10: 54 | C10: 18.5 | D10: 0.32 | E10: =B10*1.5 | F10: =(B10+C10)*(1+D10)
A12: Burden default 32% covers WC + GL + FICA/Medicare + SUTA/FUTA. Verify against your insurance certificates + payroll service for accuracy. Prevailing-wage jobs may require federal Davis-Bacon wage determinations — see Universal Sub Suite's Certified Payroll guide.

Sheet Material Takeoff
A1: MATERIAL TAKEOFF (CSI Division 22)
A3: CSI Code | B3: Description | C3: QTY | D3: UOM | E3: Unit Cost ($) | F3: Material Subtotal ($) | G3: Notes
A4: 22 11 00 | B4: Domestic water — CPVC piping, 1/2" | C4: 0 | D4: LF | E4: 1.85 | F4: =C4*E4
A5: 22 11 00 | B5: Domestic water — CPVC piping, 3/4" | C5: 0 | D5: LF | E5: 2.4 | F5: =C5*E5
A6: 22 11 00 | B6: Domestic water — CPVC piping, 1" | C6: 0 | D6: LF | E6: 3.2 | F6: =C6*E6
A7: 22 11 00 | B7: Domestic water — CPVC piping, 1-1/2" | C7: 0 | D7: LF | E7: 4.85 | F7: =C7*E7
A8: 22 11 00 | B8: Domestic water — CPVC piping, 2" | C8: 0 | D8: LF | E8: 6.1 | F8: =C8*E8
A9: 22 11 00 | B9: Domestic water — PEX-A piping, 1/2" | C9: 0 | D9: LF | E9: 0.95 | F9: =C9*E9 | G9: Crimp/cinch connections
A10: 22 11 00 | B10: Domestic water — PEX-A piping, 3/4" | C10: 0 | D10: LF | E10: 1.45 | F10: =C10*E10
A11: 22 11 00 | B11: Domestic water — Copper Type L, 1/2" | C11: 0 | D11: LF | E11: 4.75 | F11: =C11*E11 | G11: Soldered + ProPress
A12: 22 11 00 | B12: Domestic water — Copper Type L, 3/4" | C12: 0 | D12: LF | E12: 6.85 | F12: =C12*E12
A13: 22 11 00 | B13: Domestic water — Copper Type L, 1" | C13: 0 | D13: LF | E13: 9.4 | F13: =C13*E13
A14: 22 11 00 | B14: Water service entry — 1.5" - 2" | C14: 0 | D14: EA | E14: 425 | F14: =C14*E14 | G14: Includes meter loop, BFP
A15: 22 11 00 | B15: Backflow preventer — RPZ, 1" | C15: 0 | D15: EA | E15: 1875 | F15: =C15*E15
A16: 22 11 00 | B16: Backflow preventer — DCV, 1" | C16: 0 | D16: EA | E16: 875 | F16: =C16*E16
A17: 22 11 00 | B17: Water hammer arrestor | C17: 0 | D17: EA | E17: 38 | F17: =C17*E17
A18: 22 11 19 | B18: Pipe insulation — 1/2" copper | C18: 0 | D18: LF | E18: 1.45 | F18: =C18*E18
A19: 22 11 19 | B19: Pipe insulation — 1" copper | C19: 0 | D19: LF | E19: 2.2 | F19: =C19*E19
A20: 22 11 19 | B20: Pipe insulation — 2" copper/CPVC | C20: 0 | D20: LF | E20: 3.4 | F20: =C20*E20
A21: 22 13 16 | B21: Sanitary DWV — PVC, 2" Sch 40 | C21: 0 | D21: LF | E21: 2.85 | F21: =C21*E21
A22: 22 13 16 | B22: Sanitary DWV — PVC, 3" Sch 40 | C22: 0 | D22: LF | E22: 4.2 | F22: =C22*E22
A23: 22 13 16 | B23: Sanitary DWV — PVC, 4" Sch 40 | C23: 0 | D23: LF | E23: 5.95 | F23: =C23*E23
A24: 22 13 16 | B24: Sanitary DWV — PVC, 6" Sch 40 | C24: 0 | D24: LF | E24: 9.75 | F24: =C24*E24
A25: 22 13 16 | B25: Cast iron DWV — 4" no-hub | C25: 0 | D25: LF | E25: 24.5 | F25: =C25*E25 | G25: Service-weight hub-and-spigot uplift
A26: 22 13 16 | B26: Cast iron DWV — 6" no-hub | C26: 0 | D26: LF | E26: 38 | F26: =C26*E26
A27: 22 13 19 | B27: Floor drain — 2" w/ trap primer | C27: 0 | D27: EA | E27: 145 | F27: =C27*E27
A28: 22 13 19 | B28: Floor drain — 4" w/ trap primer | C28: 0 | D28: EA | E28: 215 | F28: =C28*E28
A29: 22 13 19 | B29: Roof drain — 4" w/ scupper overflow | C29: 0 | D29: EA | E29: 285 | F29: =C29*E29
A30: 22 13 19 | B30: Cleanout — wall, 4" | C30: 0 | D30: EA | E30: 95 | F30: =C30*E30
A31: 22 13 19 | B31: Cleanout — floor, 4" | C31: 0 | D31: EA | E31: 125 | F31: =C31*E31
A32: 22 13 23 | B32: Grease interceptor — 50 GPM | C32: 0 | D32: EA | E32: 3850 | F32: =C32*E32 | G32: Hydromechanical
A33: 22 13 23 | B33: Grease interceptor — 75 GPM | C33: 0 | D33: EA | E33: 5250 | F33: =C33*E33
A34: 22 13 29 | B34: Sewage ejector pump — duplex 1HP | C34: 0 | D34: EA | E34: 2950 | F34: =C34*E34
A35: 22 14 13 | B35: Storm DWV — PVC, 4" | C35: 0 | D35: LF | E35: 5.95 | F35: =C35*E35
A36: 22 14 13 | B36: Storm DWV — PVC, 6" | C36: 0 | D36: LF | E36: 9.75 | F36: =C36*E36
A37: 22 14 13 | B37: Storm DWV — PVC, 8" | C37: 0 | D37: LF | E37: 14.5 | F37: =C37*E37
A38: 22 33 30 | B38: Electric water heater — 40 gal | C38: 0 | D38: EA | E38: 685 | F38: =C38*E38
A39: 22 33 30 | B39: Electric water heater — 80 gal | C39: 0 | D39: EA | E39: 1245 | F39: =C39*E39
A40: 22 33 33 | B40: Gas water heater — 50 gal, atmospheric | C40: 0 | D40: EA | E40: 1485 | F40: =C40*E40
A41: 22 33 36 | B41: Gas water heater — 75 gal, power-vent | C41: 0 | D41: EA | E41: 2150 | F41: =C41*E41
...

Sheet Labor Estimate
A1: LABOR ESTIMATE (PHCC/MCAA-style labor units)
A3: CSI Code | B3: Activity | C3: QTY | D3: UOM | E3: Hours / UOM | F3: Subtotal Hours | G3: Crew Loaded Rate ($/hr) | H3: Subtotal Labor ($)
A4: 22 42 13 | B4: Set water closet — flushometer | C4: 0 | D4: EA | E4: 1.85 | F4: =C4*E4 | G4: 65 | H4: =F4*G4
A5: 22 42 13 | B5: Set water closet — tank type | C5: 0 | D5: EA | E5: 1.2 | F5: =C5*E5 | G5: 65 | H5: =F5*G5
A6: 22 42 16 | B6: Set urinal — flushometer | C6: 0 | D6: EA | E6: 1.65 | F6: =C6*E6 | G6: 65 | H6: =F6*G6
A7: 22 42 19 | B7: Set lavatory — wall-hung | C7: 0 | D7: EA | E7: 1.45 | F7: =C7*E7 | G7: 65 | H7: =F7*G7
A8: 22 42 19 | B8: Set lavatory — countertop | C8: 0 | D8: EA | E8: 1.2 | F8: =C8*E8 | G8: 65 | H8: =F8*G8
A9: 22 42 23 | B9: Set sink — single-bowl | C9: 0 | D9: EA | E9: 1.3 | F9: =C9*E9 | G9: 65 | H9: =F9*G9
A10: 22 42 23 | B10: Set sink — three-compartment | C10: 0 | D10: EA | E10: 2.5 | F10: =C10*E10 | G10: 65 | H10: =F10*G10
A11: 22 42 26 | B11: Set service / mop sink | C11: 0 | D11: EA | E11: 2.1 | F11: =C11*E11 | G11: 65 | H11: =F11*G11
A12: 22 42 33 | B12: Set shower w/ valve + head | C12: 0 | D12: EA | E12: 2.75 | F12: =C12*E12 | G12: 65 | H12: =F12*G12
A13: 22 42 39 | B13: Set drinking fountain — ADA | C13: 0 | D13: EA | E13: 2.4 | F13: =C13*E13 | G13: 65 | H13: =F13*G13
A14: 22 45 00 | B14: Set emergency eyewash + shower | C14: 0 | D14: EA | E14: 4.25 | F14: =C14*E14 | G14: 65 | H14: =F14*G14
A15: 22 33 30 | B15: Set electric water heater — 40 gal | C15: 0 | D15: EA | E15: 3.5 | F15: =C15*E15 | G15: 65 | H15: =F15*G15
... A47: 22 08 00 | B47: Gas pressure test | C47: 0 | D47: LS | E47: 8 | F47: =C47*E47 | G47: 70 | H47: =F47*G47
G49: Productivity factor (1.0=avg) | H49: 1
G50: Labor Subtotal | H50: =SUM(H4:H47)*H49
A51: Productivity defaults assume average commercial conditions with reasonable access and standard sequencing. Increase the productivity factor for difficult work (occupied buildings, extensive demolition, hazmat). Decrease for repetitive prefab or unobstructed greenfield. Calibrate against your own historical job-cost data.

Sheet Equipment
A1: EQUIPMENT ESTIMATE
A3: Equipment | B3: Days | C3: Daily Rate ($) | D3: Weeks | E3: Weekly Rate ($) | F3: Subtotal ($)
A4: Threading machine — 1/2" - 2" | B4: 0 | C4: 145 | D4: 0 | E4: 525 | F4: =(B4*C4)+(D4*E4)
A5: Threading machine — 2-1/2" - 4" | B5: 0 | C5: 285 | D5: 0 | E5: 985 | F5: =(B5*C5)+(D5*E5)
A6: Press tool — ProPress copper | B6: 0 | C6: 95 | D6: 0 | E6: 285 | F6: =(B6*C6)+(D6*E6)
A7: PEX expansion tool | B7: 0 | C7: 65 | D7: 0 | E7: 195 | F7: =(B7*C7)+(D7*E7)
A8: Fusion welder — HDPE | B8: 0 | C8: 425 | D8: 0 | E8: 1450 | F8: =(B8*C8)+(D8*E8)
A9: Pipe-bending machine — conduit/CSST | B9: 0 | C9: 85 | D9: 0 | E9: 245 | F9: =(B9*C9)+(D9*E9)
A10: Scissor lift — 19' | B10: 0 | C10: 145 | D10: 0 | E10: 485 | F10: =(B10*C10)+(D10*E10)
A11: Boom lift — 45' | B11: 0 | C11: 425 | D11: 0 | E11: 1485 | F11: =(B11*C11)+(D11*E11)
A12: Genie / personnel lift — 20' | B12: 0 | C12: 85 | D12: 0 | E12: 285 | F12: =(B12*C12)+(D12*E12)
A13: Test pump — hydrostatic | B13: 0 | C13: 55 | D13: 0 | E13: 165 | F13: =(B13*C13)+(D13*E13)
A14: Drain camera — push | B14: 0 | C14: 95 | D14: 0 | E14: 325 | F14: =(B14*C14)+(D14*E14)
A15: Trencher / mini-excavator | B15: 0 | C15: 385 | D15: 0 | E15: 1450 | F15: =(B15*C15)+(D15*E15)
... A20: Truck / van allocation | B20: 0 | C20: 0 | D20: 0 | E20: 425 | F20: =(B20*C20)+(D20*E20)
E22: Equipment Subtotal | F22: =SUM(F4:F20)

Sheet Subcontract
A1: SUBCONTRACT ESTIMATE
A3: Scope (if subbed) | B3: Vendor / Quote | C3: Quote $ | D3: Markup % | E3: Subtotal ($)
A4: Pipe insulation — performance-spec | C4: 0 | D4: 0.1 | E4: =C4*(1+D4)
A5: Excavation / backfill (deep utilities) | C5: 0 | D5: 0.1 | E5: =C5*(1+D5)
A6: Site utility tie-ins | C6: 0 | D6: 0.1 | E6: =C6*(1+D6)
A7: Medical gas certification | C7: 0 | D7: 0.1 | E7: =C7*(1+D7)
A8: Fire-stop installer (specialty) | C8: 0 | D8: 0.1 | E8: =C8*(1+D8)
A9: Control wiring (if not by EC) | C9: 0 | D9: 0.1 | E9: =C9*(1+D9)
A10: Concrete saw-cutting / core drilling | C10: 0 | D10: 0.1 | E10: =C10*(1+D10)
A11: Engineered shop drawings (CAD) | C11: 0 | D11: 0.1 | E11: =C11*(1+D11)
A12: Hot work fire watch (after-hours) | C12: 0 | D12: 0.1 | E12: =C12*(1+D12)
A13: Hazmat / lead-paint disturbance | C13: 0 | D13: 0.1 | E13: =C13*(1+D13)
D15: Subcontract Subtotal | E15: =SUM(E4:E13)

Sheet Premiums
A1: PREMIUMS & CONDITIONS
A3: Premium | B3: Applies? (Y/N) | C3: Adder % | D3: Adder $ (overrides %)
A4: Prevailing wage (Davis-Bacon or state) | B4: N | C4: 0.15 | D4: 0
A5: Occupied building disruption | B5: N | C5: 0.08 | D5: 0
A6: Confined-space entry frequency | B6: N | C6: 0.04 | D6: 0
A7: Hazmat-area (asbestos / lead / silica) | B7: N | C7: 0.1 | D7: 0
A8: Energized-system / hot-tap proximity | B8: N | C8: 0.05 | D8: 0
A9: Hospital ICRA (infection-control) tier 3+ | B9: N | C9: 0.08 | D9: 0
A10: Heights > 14 ft (lift / scaffold premium) | B10: N | C10: 0.04 | D10: 0
A11: Underground utility congestion | B11: N | C11: 0.06 | D11: 0
A12: Tight crawl-space / attic conditions | B12: N | C12: 0.05 | D12: 0
A13: After-hours / weekend / night shift | B13: N | C13: 0.2 | D13: 0
A14: Travel / per diem | B14: N | C14: 0.03 | D14: 0
A15: Winter weather conditions | B15: N | C15: 0.04 | D15: 0
... A17: Owner-direct purchasing (no markup) | B17: N | C17: -0.1 | D17: 0
A19: Premium $ total (applies-Y only) | D19: =SUMPRODUCT((B4:B17="Y")*D4:D17)
A20: Premium % total (applies-Y only) | D20: =SUMPRODUCT((B4:B17="Y")*C4:C17)

Sheet CSI Reference
A1: CSI MASTERFORMAT — DIVISION 22 PLUMBING
A3: 22 00 00 | B3: PLUMBING (overall division)
A4: 22 05 00 | B4: Common Work Results for Plumbing
A5: 22 05 19 | B5: Meters and Gauges for Plumbing Piping
A6: 22 05 23 | B6: General-Duty Valves for Plumbing Piping
A7: 22 05 29 | B7: Hangers and Supports for Plumbing Piping and Equipment
A8: 22 05 53 | B8: Identification for Plumbing Piping and Equipment
A9: 22 07 00 | B9: Plumbing Insulation
A10: 22 08 00 | B10: Commissioning of Plumbing
A11: 22 11 00 | B11: Facility Water Distribution
A12: 22 11 13 | B12: Facility Water Distribution Piping
A13: 22 11 16 | B13: Domestic Water Piping
A14: 22 11 19 | B14: Domestic Water Piping Specialties
... A49: 22 67 00 | B49: Processed Water Systems for Laboratory and Healthcare Facilities
