Workbook
Name ProjectName: 'Project Info'!$C$3
Name GCName: 'Project Info'!$C$5
Name SubName: 'Project Info'!$C$7
Name TradeScope: 'Project Info'!$C$8
Name Foreman: 'Project Info'!$C$10
Name FirstDay: 'Project Info'!$C$13

Sheet Instructions
A1: DAILY FIELD REPORT — Instructions
A3: WHAT THIS WORKBOOK IS
A4: Digital companion to the printable DFR (daily-field-report-template-and-guide.html). This workbook provides one tab per day for a single calendar month (Day 01 through Day 31), plus a Monthly Roll-Up tab that aggregates labor hours, crew counts, equipment hours, safety incidents, and weather lost-time. Use one workbook per project per month.
A6: DAILY WORKFLOW
A7: 1. Open the appropriate Day tab at the start of the shift.
A8: 2. Foreman enters crew, classification, hours, and tasks throughout the day or at end of shift.
A9: 3. Materials delivered, equipment used, conditions affecting work, directives, RFIs, photos, safety, and visitors logged.
A10: 4. Sign in the Foreman field. Request GC field-rep countersignature where practical.
A11: 5. Save and back up the workbook the same day.
A13: MONTHLY ROLL-UP
A14: The Monthly Roll-Up tab pulls totals from each Day tab automatically. Submit the roll-up with the monthly pay app or to the GC PM as the consolidated monthly report.
A16: MULTIPLE PROJECTS / MONTHS
... A26: Save each completed Day tab as PDF at end-of-week and store with the project file. Excel files can be edited; PDF snapshots cannot. Both should exist.

Sheet Project Info
B1: PROJECT INFORMATION
B3: Project Name
B4: Project Address
B5: GC
B6: Owner
B7: Subcontractor (legal name)
B8: Trade / Scope
B9: Subcontract No.
B10: Foreman
B11: Sub's PM
B12: Month (YYYY-MM)
B13: First Day of Month (date)

Sheet Monthly Roll-Up
B1: MONTHLY ROLL-UP
B2: Auto-aggregated from Day 01 through Day 31 tabs. Blank rows = day not yet logged.
B4: Day | C4: Date | D4: ST Hrs | E4: OT Hrs | F4: Total Hrs | G4: Equip Op Hrs | H4: Weather Lost Hrs | I4: Recordable Inc.
B5: 1 | C5: =IF(FirstDay="","",FirstDay+0) | D5: ='Day 01'!B200 | E5: ='Day 01'!B201 | F5: =D5+E5 | G5: ='Day 01'!B202 | H5: ='Day 01'!B203 | I5: ='Day 01'!B204
B6: 2 | C6: =IF(FirstDay="","",FirstDay+1) | D6: ='Day 02'!B200 | E6: ='Day 02'!B201 | F6: =D6+E6 | G6: ='Day 02'!B202 | H6: ='Day 02'!B203 | I6: ='Day 02'!B204
B7: 3 | C7: =IF(FirstDay="","",FirstDay+2) | D7: ='Day 03'!B200 | E7: ='Day 03'!B201 | F7: =D7+E7 | G7: ='Day 03'!B202 | H7: ='Day 03'!B203 | I7: ='Day 03'!B204
B8: 4 | C8: =IF(FirstDay="","",FirstDay+3) | D8: ='Day 04'!B200 | E8: ='Day 04'!B201 | F8: =D8+E8 | G8: ='Day 04'!B202 | H8: ='Day 04'!B203 | I8: ='Day 04'!B204
B9: 5 | C9: =IF(FirstDay="","",FirstDay+4) | D9: ='Day 05'!B200 | E9: ='Day 05'!B201 | F9: =D9+E9 | G9: ='Day 05'!B202 | H9: ='Day 05'!B203 | I9: ='Day 05'!B204
B10: 6 | C10: =IF(FirstDay="","",FirstDay+5) | D10: ='Day 06'!B200 | E10: ='Day 06'!B201 | F10: =D10+E10 | G10: ='Day 06'!B202 | H10: ='Day 06'!B203 | I10: ='Day 06'!B204
B11: 7 | C11: =IF(FirstDay="","",FirstDay+6) | D11: ='Day 07'!B200 | E11: ='Day 07'!B201 | F11: =D11+E11 | G11: ='Day 07'!B202 | H11: ='Day 07'!B203 | I11: ='Day 07'!B204
B12: 8 | C12: =IF(FirstDay="","",FirstDay+7) | D12: ='Day 08'!B200 | E12: ='Day 08'!B201 | F12: =D12+E12 | G12: ='Day 08'!B202 | H12: ='Day 08'!B203 | I12: ='Day 08'!B204
B13: 9 | C13: =IF(FirstDay="","",FirstDay+8) | D13: ='Day 09'!B200 | E13: ='Day 09'!B201 | F13: =D13+E13 | G13: ='Day 09'!B202 | H13: ='Day 09'!B203 | I13: ='Day 09'!B204
B14: 10 | C14: =IF(FirstDay="","",FirstDay+9) | D14: ='Day 10'!B200 | E14: ='Day 10'!B201 | F14: =D14+E14 | G14: ='Day 10'!B202 | H14: ='Day 10'!B203 | I14: ='Day 10'!B204
B15: 11 | C15: =IF(FirstDay="","",FirstDay+10) | D15: ='Day 11'!B200 | E15: ='Day 11'!B201 | F15: =D15+E15 | G15: ='Day 11'!B202 | H15: ='Day 11'!B203 | I15: ='Day 11'!B204
B16: 12 | C16: =IF(FirstDay="","",FirstDay+11) | D16: ='Day 12'!B200 | E16: ='Day 12'!B201 | F16: =D16+E16 | G16: ='Day 12'!B202 | H16: ='Day 12'!B203 | I16: ='Day 12'!B204
B17: 13 | C17: =IF(FirstDay="","",FirstDay+12) | D17: ='Day 13'!B200 | E17: ='Day 13'!B201 | F17: =D17+E17 | G17: ='Day 13'!B202 | H17: ='Day 13'!B203 | I17: ='Day 13'!B204
B18: 14 | C18: =IF(FirstDay="","",FirstDay+13) | D18: ='Day 14'!B200 | E18: ='Day 14'!B201 | F18: =D18+E18 | G18: ='Day 14'!B202 | H18: ='Day 14'!B203 | I18: ='Day 14'!B204
B19: 15 | C19: =IF(FirstDay="","",FirstDay+14) | D19: ='Day 15'!B200 | E19: ='Day 15'!B201 | F19: =D19+E19 | G19: ='Day 15'!B202 | H19: ='Day 15'!B203 | I19: ='Day 15'!B204
B20: 16 | C20: =IF(FirstDay="","",FirstDay+15) | D20: ='Day 16'!B200 | E20: ='Day 16'!B201 | F20: =D20+E20 | G20: ='Day 16'!B202 | H20: ='Day 16'!B203 | I20: ='Day 16'!B204
B21: 17 | C21: =IF(FirstDay="","",FirstDay+16) | D21: ='Day 17'!B200 | E21: ='Day 17'!B201 | F21: =D21+E21 | G21: ='Day 17'!B202 | H21: ='Day 17'!B203 | I21: ='Day 17'!B204
B22: 18 | C22: =IF(FirstDay="","",FirstDay+17) | D22: ='Day 18'!B200 | E22: ='Day 18'!B201 | F22: =D22+E22 | G22: ='Day 18'!B202 | H22: ='Day 18'!B203 | I22: ='Day 18'!B204
B23: 19 | C23: =IF(FirstDay="","",FirstDay+18) | D23: ='Day 19'!B200 | E23: ='Day 19'!B201 | F23: =D23+E23 | G23: ='Day 19'!B202 | H23: ='Day 19'!B203 | I23: ='Day 19'!B204
B24: 20 | C24: =IF(FirstDay="","",FirstDay+19) | D24: ='Day 20'!B200 | E24: ='Day 20'!B201 | F24: =D24+E24 | G24: ='Day 20'!B202 | H24: ='Day 20'!B203 | I24: ='Day 20'!B204
B25: 21 | C25: =IF(FirstDay="","",FirstDay+20) | D25: ='Day 21'!B200 | E25: ='Day 21'!B201 | F25: =D25+E25 | G25: ='Day 21'!B202 | H25: ='Day 21'!B203 | I25: ='Day 21'!B204
B26: 22 | C26: =IF(FirstDay="","",FirstDay+21) | D26: ='Day 22'!B200 | E26: ='Day 22'!B201 | F26: =D26+E26 | G26: ='Day 22'!B202 | H26: ='Day 22'!B203 | I26: ='Day 22'!B204
B27: 23 | C27: =IF(FirstDay="","",FirstDay+22) | D27: ='Day 23'!B200 | E27: ='Day 23'!B201 | F27: =D27+E27 | G27: ='Day 23'!B202 | H27: ='Day 23'!B203 | I27: ='Day 23'!B204
B28: 24 | C28: =IF(FirstDay="","",FirstDay+23) | D28: ='Day 24'!B200 | E28: ='Day 24'!B201 | F28: =D28+E28 | G28: ='Day 24'!B202 | H28: ='Day 24'!B203 | I28: ='Day 24'!B204
B29: 25 | C29: =IF(FirstDay="","",FirstDay+24) | D29: ='Day 25'!B200 | E29: ='Day 25'!B201 | F29: =D29+E29 | G29: ='Day 25'!B202 | H29: ='Day 25'!B203 | I29: ='Day 25'!B204
B30: 26 | C30: =IF(FirstDay="","",FirstDay+25) | D30: ='Day 26'!B200 | E30: ='Day 26'!B201 | F30: =D30+E30 | G30: ='Day 26'!B202 | H30: ='Day 26'!B203 | I30: ='Day 26'!B204
B31: 27 | C31: =IF(FirstDay="","",FirstDay+26) | D31: ='Day 27'!B200 | E31: ='Day 27'!B201 | F31: =D31+E31 | G31: ='Day 27'!B202 | H31: ='Day 27'!B203 | I31: ='Day 27'!B204
B32: 28 | C32: =IF(FirstDay="","",FirstDay+27) | D32: ='Day 28'!B200 | E32: ='Day 28'!B201 | F32: =D32+E32 | G32: ='Day 28'!B202 | H32: ='Day 28'!B203 | I32: ='Day 28'!B204
B33: 29 | C33: =IF(FirstDay="","",FirstDay+28) | D33: ='Day 29'!B200 | E33: ='Day 29'!B201 | F33: =D33+E33 | G33: ='Day 29'!B202 | H33: ='Day 29'!B203 | I33: ='Day 29'!B204
B34: 30 | C34: =IF(FirstDay="","",FirstDay+29) | D34: ='Day 30'!B200 | E34: ='Day 30'!B201 | F34: =D34+E34 | G34: ='Day 30'!B202 | H34: ='Day 30'!B203 | I34: ='Day 30'!B204
B35: 31 | C35: =IF(FirstDay="","",FirstDay+30) | D35: ='Day 31'!B200 | E35: ='Day 31'!B201 | F35: =D35+E35 | G35: ='Day 31'!B202 | H35: ='Day 31'!B203 | I35: ='Day 31'!B204
B36: MONTH TOTAL | D36: =SUM(D5:D35) | E36: =SUM(E5:E35) | F36: =SUM(F5:F35) | G36: =SUM(G5:G35) | H36: =SUM(H5:H35) | I36: =SUM(I5:I35)

Sheet Day 01
B1: DAILY FIELD REPORT — Day 1
B2: DFR #: | D2: Date: | E2: =IF(FirstDay="","",FirstDay+0) | F2: Project: =ProjectName
B3: Foreman: | C3: =Foreman | D3: Sub: | E3: =SubName
B5: WEATHER
B6: AM Temp (°F) / Conditions
B7: PM Temp (°F) / Conditions
B8: Wind / Visibility
B9: Impact on Work (None / Minor / Hours lost #)
B10: Idle Hours Lost to Weather | C10: 0
B12: CREW ON SITE
B13: Name | C13: Classification | D13: ST Hrs | E13: OT Hrs | F13: Task / Location
B24: CREW TOTALS | D24: =SUM(D14:D23) | E24: =SUM(E14:E23)
B26: EQUIPMENT ON SITE
B27: Equipment | C27: Owned / Rented | D27: Op Hrs | E27: Idle Hrs | F27: Notes
B34: EQUIP TOTALS | D34: =SUM(D28:D33) | E34: =SUM(E28:E33)
B36: MATERIALS DELIVERED / INSTALLED
B37: Material | C37: Supplier | D37: Qty Delivered | E37: Qty Installed | F37: Location
B45: WORK PERFORMED (NARRATIVE)
B51: CONDITIONS AFFECTING WORK
B52: Differing site conditions
B53: Missing GC trade / access
B54: Utility / power issue
B55: Inspection / AHJ
B56: Idle crew hours due to conditions (#)
B58: DIRECTIVES / RFIs / T&M TICKETS
B59: Type | C59: Originator | D59: Description | E59: Status | F59: Notes
B66: SAFETY
B67: Toolbox topic
B68: Near-miss (count) | C68: 0
B69: First aid only (count) | C69: 0
B70: Recordable incident (count) | C70: 0
B71: OSHA visit | C71: No
B72: PPE audit notes
B74: PHOTO LOG
B75: File / Frame | C75: Time | D75: Location | E75: Description | F75: Notes
B85: SIGNATURES
B86: Foreman:
B87: GC Field Rep (countersig):
A200: Anchor:CrewST | B200: =D24
A201: Anchor:CrewOT | B201: =E24
...

Sheet Day 02
B1: DAILY FIELD REPORT — Day 2
B2: DFR #: | D2: Date: | E2: =IF(FirstDay="","",FirstDay+1) | F2: Project: =ProjectName
B3: Foreman: | C3: =Foreman | D3: Sub: | E3: =SubName
B5: WEATHER
B6: AM Temp (°F) / Conditions
B7: PM Temp (°F) / Conditions
B8: Wind / Visibility
B9: Impact on Work (None / Minor / Hours lost #)
B10: Idle Hours Lost to Weather | C10: 0
B12: CREW ON SITE
B13: Name | C13: Classification | D13: ST Hrs | E13: OT Hrs | F13: Task / Location
B24: CREW TOTALS | D24: =SUM(D14:D23) | E24: =SUM(E14:E23)
B26: EQUIPMENT ON SITE
B27: Equipment | C27: Owned / Rented | D27: Op Hrs | E27: Idle Hrs | F27: Notes
B34: EQUIP TOTALS | D34: =SUM(D28:D33) | E34: =SUM(E28:E33)
B36: MATERIALS DELIVERED / INSTALLED
B37: Material | C37: Supplier | D37: Qty Delivered | E37: Qty Installed | F37: Location
B45: WORK PERFORMED (NARRATIVE)
B51: CONDITIONS AFFECTING WORK
B52: Differing site conditions
B53: Missing GC trade / access
B54: Utility / power issue
B55: Inspection / AHJ
B56: Idle crew hours due to conditions (#)
B58: DIRECTIVES / RFIs / T&M TICKETS
B59: Type | C59: Originator | D59: Description | E59: Status | F59: Notes
B66: SAFETY
B67: Toolbox topic
B68: Near-miss (count) | C68: 0
B69: First aid only (count) | C69: 0
B70: Recordable incident (count) | C70: 0
B71: OSHA visit | C71: No
B72: PPE audit notes
B74: PHOTO LOG
B75: File / Frame | C75: Time | D75: Location | E75: Description | F75: Notes
B85: SIGNATURES
B86: Foreman:
B87: GC Field Rep (countersig):
A200: Anchor:CrewST | B200: =D24
A201: Anchor:CrewOT | B201: =E24
...

Sheet Day 03
B1: DAILY FIELD REPORT — Day 3
B2: DFR #: | D2: Date: | E2: =IF(FirstDay="","",FirstDay+2) | F2: Project: =ProjectName
B3: Foreman: | C3: =Foreman | D3: Sub: | E3: =SubName
B5: WEATHER
B6: AM Temp (°F) / Conditions
B7: PM Temp (°F) / Conditions
B8: Wind / Visibility
B9: Impact on Work (None / Minor / Hours lost #)
B10: Idle Hours Lost to Weather | C10: 0
B12: CREW ON SITE
B13: Name | C13: Classification | D13: ST Hrs | E13: OT Hrs | F13: Task / Location
B24: CREW TOTALS | D24: =SUM(D14:D23) | E24: =SUM(E14:E23)
B26: EQUIPMENT ON SITE
B27: Equipment | C27: Owned / Rented | D27: Op Hrs | E27: Idle Hrs | F27: Notes
B34: EQUIP TOTALS | D34: =SUM(D28:D33) | E34: =SUM(E28:E33)
B36: MATERIALS DELIVERED / INSTALLED
B37: Material | C37: Supplier | D37: Qty Delivered | E37: Qty Installed | F37: Location
B45: WORK PERFORMED (NARRATIVE)
B51: CONDITIONS AFFECTING WORK
B52: Differing site conditions
B53: Missing GC trade / access
B54: Utility / power issue
B55: Inspection / AHJ
B56: Idle crew hours due to conditions (#)
B58: DIRECTIVES / RFIs / T&M TICKETS
B59: Type | C59: Originator | D59: Description | E59: Status | F59: Notes
B66: SAFETY
B67: Toolbox topic
B68: Near-miss (count) | C68: 0
B69: First aid only (count) | C69: 0
B70: Recordable incident (count) | C70: 0
B71: OSHA visit | C71: No
B72: PPE audit notes
B74: PHOTO LOG
B75: File / Frame | C75: Time | D75: Location | E75: Description | F75: Notes
B85: SIGNATURES
B86: Foreman:
B87: GC Field Rep (countersig):
A200: Anchor:CrewST | B200: =D24
A201: Anchor:CrewOT | B201: =E24
...

Sheet Day 04
B1: DAILY FIELD REPORT — Day 4
B2: DFR #: | D2: Date: | E2: =IF(FirstDay="","",FirstDay+3) | F2: Project: =ProjectName
B3: Foreman: | C3: =Foreman | D3: Sub: | E3: =SubName
B5: WEATHER
B6: AM Temp (°F) / Conditions
B7: PM Temp (°F) / Conditions
B8: Wind / Visibility
B9: Impact on Work (None / Minor / Hours lost #)
B10: Idle Hours Lost to Weather | C10: 0
B12: CREW ON SITE
B13: Name | C13: Classification | D13: ST Hrs | E13: OT Hrs | F13: Task / Location
B24: CREW TOTALS | D24: =SUM(D14:D23) | E24: =SUM(E14:E23)
B26: EQUIPMENT ON SITE
B27: Equipment | C27: Owned / Rented | D27: Op Hrs | E27: Idle Hrs | F27: Notes
B34: EQUIP TOTALS | D34: =SUM(D28:D33) | E34: =SUM(E28:E33)
B36: MATERIALS DELIVERED / INSTALLED
B37: Material | C37: Supplier | D37: Qty Delivered | E37: Qty Installed | F37: Location
B45: WORK PERFORMED (NARRATIVE)
B51: CONDITIONS AFFECTING WORK
B52: Differing site conditions
B53: Missing GC trade / access
B54: Utility / power issue
B55: Inspection / AHJ
B56: Idle crew hours due to conditions (#)
B58: DIRECTIVES / RFIs / T&M TICKETS
B59: Type | C59: Originator | D59: Description | E59: Status | F59: Notes
B66: SAFETY
B67: Toolbox topic
B68: Near-miss (count) | C68: 0
B69: First aid only (count) | C69: 0
B70: Recordable incident (count) | C70: 0
B71: OSHA visit | C71: No
B72: PPE audit notes
B74: PHOTO LOG
B75: File / Frame | C75: Time | D75: Location | E75: Description | F75: Notes
B85: SIGNATURES
B86: Foreman:
B87: GC Field Rep (countersig):
A200: Anchor:CrewST | B200: =D24
A201: Anchor:CrewOT | B201: =E24
...

Sheet Day 05
B1: DAILY FIELD REPORT — Day 5
B2: DFR #: | D2: Date: | E2: =IF(FirstDay="","",FirstDay+4) | F2: Project: =ProjectName
B3: Foreman: | C3: =Foreman | D3: Sub: | E3: =SubName
B5: WEATHER
B6: AM Temp (°F) / Conditions
B7: PM Temp (°F) / Conditions
B8: Wind / Visibility
B9: Impact on Work (None / Minor / Hours lost #)
B10: Idle Hours Lost to Weather | C10: 0
B12: CREW ON SITE
B13: Name | C13: Classification | D13: ST Hrs | E13: OT Hrs | F13: Task / Location
B24: CREW TOTALS | D24: =SUM(D14:D23) | E24: =SUM(E14:E23)
B26: EQUIPMENT ON SITE
B27: Equipment | C27: Owned / Rented | D27: Op Hrs | E27: Idle Hrs | F27: Notes
B34: EQUIP TOTALS | D34: =SUM(D28:D33) | E34: =SUM(E28:E33)
B36: MATERIALS DELIVERED / INSTALLED
B37: Material | C37: Supplier | D37: Qty Delivered | E37: Qty Installed | F37: Location
B45: WORK PERFORMED (NARRATIVE)
B51: CONDITIONS AFFECTING WORK
B52: Differing site conditions
B53: Missing GC trade / access
B54: Utility / power issue
B55: Inspection / AHJ
B56: Idle crew hours due to conditions (#)
B58: DIRECTIVES / RFIs / T&M TICKETS
B59: Type | C59: Originator | D59: Description | E59: Status | F59: Notes
B66: SAFETY
B67: Toolbox topic
B68: Near-miss (count) | C68: 0
B69: First aid only (count) | C69: 0
B70: Recordable incident (count) | C70: 0
B71: OSHA visit | C71: No
B72: PPE audit notes
B74: PHOTO LOG
B75: File / Frame | C75: Time | D75: Location | E75: Description | F75: Notes
B85: SIGNATURES
B86: Foreman:
B87: GC Field Rep (countersig):
A200: Anchor:CrewST | B200: =D24
A201: Anchor:CrewOT | B201: =E24
...

Sheet Day 06
B1: DAILY FIELD REPORT — Day 6
B2: DFR #: | D2: Date: | E2: =IF(FirstDay="","",FirstDay+5) | F2: Project: =ProjectName
B3: Foreman: | C3: =Foreman | D3: Sub: | E3: =SubName
B5: WEATHER
B6: AM Temp (°F) / Conditions
B7: PM Temp (°F) / Conditions
B8: Wind / Visibility
B9: Impact on Work (None / Minor / Hours lost #)
B10: Idle Hours Lost to Weather | C10: 0
B12: CREW ON SITE
B13: Name | C13: Classification | D13: ST Hrs | E13: OT Hrs | F13: Task / Location
B24: CREW TOTALS | D24: =SUM(D14:D23) | E24: =SUM(E14:E23)
B26: EQUIPMENT ON SITE
B27: Equipment | C27: Owned / Rented | D27: Op Hrs | E27: Idle Hrs | F27: Notes
B34: EQUIP TOTALS | D34: =SUM(D28:D33) | E34: =SUM(E28:E33)
B36: MATERIALS DELIVERED / INSTALLED
B37: Material | C37: Supplier | D37: Qty Delivered | E37: Qty Installed | F37: Location
B45: WORK PERFORMED (NARRATIVE)
B51: CONDITIONS AFFECTING WORK
B52: Differing site conditions
B53: Missing GC trade / access
B54: Utility / power issue
B55: Inspection / AHJ
B56: Idle crew hours due to conditions (#)
B58: DIRECTIVES / RFIs / T&M TICKETS
B59: Type | C59: Originator | D59: Description | E59: Status | F59: Notes
B66: SAFETY
B67: Toolbox topic
B68: Near-miss (count) | C68: 0
B69: First aid only (count) | C69: 0
B70: Recordable incident (count) | C70: 0
B71: OSHA visit | C71: No
B72: PPE audit notes
B74: PHOTO LOG
B75: File / Frame | C75: Time | D75: Location | E75: Description | F75: Notes
B85: SIGNATURES
B86: Foreman:
B87: GC Field Rep (countersig):
A200: Anchor:CrewST | B200: =D24
A201: Anchor:CrewOT | B201: =E24
...

Sheet Day 07
B1: DAILY FIELD REPORT — Day 7
B2: DFR #: | D2: Date: | E2: =IF(FirstDay="","",FirstDay+6) | F2: Project: =ProjectName
B3: Foreman: | C3: =Foreman | D3: Sub: | E3: =SubName
B5: WEATHER
B6: AM Temp (°F) / Conditions
B7: PM Temp (°F) / Conditions
B8: Wind / Visibility
B9: Impact on Work (None / Minor / Hours lost #)
B10: Idle Hours Lost to Weather | C10: 0
B12: CREW ON SITE
B13: Name | C13: Classification | D13: ST Hrs | E13: OT Hrs | F13: Task / Location
B24: CREW TOTALS | D24: =SUM(D14:D23) | E24: =SUM(E14:E23)
B26: EQUIPMENT ON SITE
B27: Equipment | C27: Owned / Rented | D27: Op Hrs | E27: Idle Hrs | F27: Notes
B34: EQUIP TOTALS | D34: =SUM(D28:D33) | E34: =SUM(E28:E33)
B36: MATERIALS DELIVERED / INSTALLED
B37: Material | C37: Supplier | D37: Qty Delivered | E37: Qty Installed | F37: Location
B45: WORK PERFORMED (NARRATIVE)
B51: CONDITIONS AFFECTING WORK
B52: Differing site conditions
B53: Missing GC trade / access
B54: Utility / power issue
B55: Inspection / AHJ
B56: Idle crew hours due to conditions (#)
B58: DIRECTIVES / RFIs / T&M TICKETS
B59: Type | C59: Originator | D59: Description | E59: Status | F59: Notes
B66: SAFETY
B67: Toolbox topic
B68: Near-miss (count) | C68: 0
B69: First aid only (count) | C69: 0
B70: Recordable incident (count) | C70: 0
B71: OSHA visit | C71: No
B72: PPE audit notes
B74: PHOTO LOG
B75: File / Frame | C75: Time | D75: Location | E75: Description | F75: Notes
B85: SIGNATURES
B86: Foreman:
B87: GC Field Rep (countersig):
A200: Anchor:CrewST | B200: =D24
A201: Anchor:CrewOT | B201: =E24
...

Sheet Day 08
B1: DAILY FIELD REPORT — Day 8
B2: DFR #: | D2: Date: | E2: =IF(FirstDay="","",FirstDay+7) | F2: Project: =ProjectName
B3: Foreman: | C3: =Foreman | D3: Sub: | E3: =SubName
B5: WEATHER
B6: AM Temp (°F) / Conditions
B7: PM Temp (°F) / Conditions
B8: Wind / Visibility
B9: Impact on Work (None / Minor / Hours lost #)
B10: Idle Hours Lost to Weather | C10: 0
B12: CREW ON SITE
B13: Name | C13: Classification | D13: ST Hrs | E13: OT Hrs | F13: Task / Location
B24: CREW TOTALS | D24: =SUM(D14:D23) | E24: =SUM(E14:E23)
B26: EQUIPMENT ON SITE
B27: Equipment | C27: Owned / Rented | D27: Op Hrs | E27: Idle Hrs | F27: Notes
B34: EQUIP TOTALS | D34: =SUM(D28:D33) | E34: =SUM(E28:E33)
B36: MATERIALS DELIVERED / INSTALLED
B37: Material | C37: Supplier | D37: Qty Delivered | E37: Qty Installed | F37: Location
B45: WORK PERFORMED (NARRATIVE)
B51: CONDITIONS AFFECTING WORK
B52: Differing site conditions
B53: Missing GC trade / access
B54: Utility / power issue
B55: Inspection / AHJ
B56: Idle crew hours due to conditions (#)
B58: DIRECTIVES / RFIs / T&M TICKETS
B59: Type | C59: Originator | D59: Description | E59: Status | F59: Notes
B66: SAFETY
B67: Toolbox topic
B68: Near-miss (count) | C68: 0
B69: First aid only (count) | C69: 0
B70: Recordable incident (count) | C70: 0
B71: OSHA visit | C71: No
B72: PPE audit notes
B74: PHOTO LOG
B75: File / Frame | C75: Time | D75: Location | E75: Description | F75: Notes
B85: SIGNATURES
B86: Foreman:
B87: GC Field Rep (countersig):
A200: Anchor:CrewST | B200: =D24
A201: Anchor:CrewOT | B201: =E24
...

Sheet Day 09
B1: DAILY FIELD REPORT — Day 9
B2: DFR #: | D2: Date: | E2: =IF(FirstDay="","",FirstDay+8) | F2: Project: =ProjectName
B3: Foreman: | C3: =Foreman | D3: Sub: | E3: =SubName
B5: WEATHER
B6: AM Temp (°F) / Conditions
B7: PM Temp (°F) / Conditions
B8: Wind / Visibility
B9: Impact on Work (None / Minor / Hours lost #)
B10: Idle Hours Lost to Weather | C10: 0
B12: CREW ON SITE
B13: Name | C13: Classification | D13: ST Hrs | E13: OT Hrs | F13: Task / Location
B24: CREW TOTALS | D24: =SUM(D14:D23) | E24: =SUM(E14:E23)
B26: EQUIPMENT ON SITE
B27: Equipment | C27: Owned / Rented | D27: Op Hrs | E27: Idle Hrs | F27: Notes
B34: EQUIP TOTALS | D34: =SUM(D28:D33) | E34: =SUM(E28:E33)
B36: MATERIALS DELIVERED / INSTALLED
B37: Material | C37: Supplier | D37: Qty Delivered | E37: Qty Installed | F37: Location
B45: WORK PERFORMED (NARRATIVE)
B51: CONDITIONS AFFECTING WORK
B52: Differing site conditions
B53: Missing GC trade / access
B54: Utility / power issue
B55: Inspection / AHJ
B56: Idle crew hours due to conditions (#)
B58: DIRECTIVES / RFIs / T&M TICKETS
B59: Type | C59: Originator | D59: Description | E59: Status | F59: Notes
B66: SAFETY
B67: Toolbox topic
B68: Near-miss (count) | C68: 0
B69: First aid only (count) | C69: 0
B70: Recordable incident (count) | C70: 0
B71: OSHA visit | C71: No
B72: PPE audit notes
B74: PHOTO LOG
B75: File / Frame | C75: Time | D75: Location | E75: Description | F75: Notes
B85: SIGNATURES
B86: Foreman:
B87: GC Field Rep (countersig):
A200: Anchor:CrewST | B200: =D24
A201: Anchor:CrewOT | B201: =E24
...

Sheet Day 10
B1: DAILY FIELD REPORT — Day 10
B2: DFR #: | D2: Date: | E2: =IF(FirstDay="","",FirstDay+9) | F2: Project: =ProjectName
B3: Foreman: | C3: =Foreman | D3: Sub: | E3: =SubName
B5: WEATHER
B6: AM Temp (°F) / Conditions
B7: PM Temp (°F) / Conditions
B8: Wind / Visibility
B9: Impact on Work (None / Minor / Hours lost #)
B10: Idle Hours Lost to Weather | C10: 0
B12: CREW ON SITE
B13: Name | C13: Classification | D13: ST Hrs | E13: OT Hrs | F13: Task / Location
B24: CREW TOTALS | D24: =SUM(D14:D23) | E24: =SUM(E14:E23)
B26: EQUIPMENT ON SITE
B27: Equipment | C27: Owned / Rented | D27: Op Hrs | E27: Idle Hrs | F27: Notes
B34: EQUIP TOTALS | D34: =SUM(D28:D33) | E34: =SUM(E28:E33)
B36: MATERIALS DELIVERED / INSTALLED
B37: Material | C37: Supplier | D37: Qty Delivered | E37: Qty Installed | F37: Location
B45: WORK PERFORMED (NARRATIVE)
B51: CONDITIONS AFFECTING WORK
B52: Differing site conditions
B53: Missing GC trade / access
B54: Utility / power issue
B55: Inspection / AHJ
B56: Idle crew hours due to conditions (#)
B58: DIRECTIVES / RFIs / T&M TICKETS
B59: Type | C59: Originator | D59: Description | E59: Status | F59: Notes
B66: SAFETY
B67: Toolbox topic
B68: Near-miss (count) | C68: 0
B69: First aid only (count) | C69: 0
B70: Recordable incident (count) | C70: 0
B71: OSHA visit | C71: No
B72: PPE audit notes
B74: PHOTO LOG
B75: File / Frame | C75: Time | D75: Location | E75: Description | F75: Notes
B85: SIGNATURES
B86: Foreman:
B87: GC Field Rep (countersig):
A200: Anchor:CrewST | B200: =D24
A201: Anchor:CrewOT | B201: =E24
...

Sheet Day 11
B1: DAILY FIELD REPORT — Day 11
B2: DFR #: | D2: Date: | E2: =IF(FirstDay="","",FirstDay+10) | F2: Project: =ProjectName
B3: Foreman: | C3: =Foreman | D3: Sub: | E3: =SubName
B5: WEATHER
B6: AM Temp (°F) / Conditions
B7: PM Temp (°F) / Conditions
B8: Wind / Visibility
B9: Impact on Work (None / Minor / Hours lost #)
B10: Idle Hours Lost to Weather | C10: 0
B12: CREW ON SITE
B13: Name | C13: Classification | D13: ST Hrs | E13: OT Hrs | F13: Task / Location
B24: CREW TOTALS | D24: =SUM(D14:D23) | E24: =SUM(E14:E23)
B26: EQUIPMENT ON SITE
B27: Equipment | C27: Owned / Rented | D27: Op Hrs | E27: Idle Hrs | F27: Notes
B34: EQUIP TOTALS | D34: =SUM(D28:D33) | E34: =SUM(E28:E33)
B36: MATERIALS DELIVERED / INSTALLED
B37: Material | C37: Supplier | D37: Qty Delivered | E37: Qty Installed | F37: Location
B45: WORK PERFORMED (NARRATIVE)
B51: CONDITIONS AFFECTING WORK
B52: Differing site conditions
B53: Missing GC trade / access
B54: Utility / power issue
B55: Inspection / AHJ
B56: Idle crew hours due to conditions (#)
B58: DIRECTIVES / RFIs / T&M TICKETS
B59: Type | C59: Originator | D59: Description | E59: Status | F59: Notes
B66: SAFETY
B67: Toolbox topic
B68: Near-miss (count) | C68: 0
B69: First aid only (count) | C69: 0
B70: Recordable incident (count) | C70: 0
B71: OSHA visit | C71: No
B72: PPE audit notes
B74: PHOTO LOG
B75: File / Frame | C75: Time | D75: Location | E75: Description | F75: Notes
B85: SIGNATURES
B86: Foreman:
B87: GC Field Rep (countersig):
A200: Anchor:CrewST | B200: =D24
A201: Anchor:CrewOT | B201: =E24
...

Sheet Day 12
B1: DAILY FIELD REPORT — Day 12
B2: DFR #: | D2: Date: | E2: =IF(FirstDay="","",FirstDay+11) | F2: Project: =ProjectName
B3: Foreman: | C3: =Foreman | D3: Sub: | E3: =SubName
B5: WEATHER
B6: AM Temp (°F) / Conditions
B7: PM Temp (°F) / Conditions
B8: Wind / Visibility
B9: Impact on Work (None / Minor / Hours lost #)
B10: Idle Hours Lost to Weather | C10: 0
B12: CREW ON SITE
B13: Name | C13: Classification | D13: ST Hrs | E13: OT Hrs | F13: Task / Location
B24: CREW TOTALS | D24: =SUM(D14:D23) | E24: =SUM(E14:E23)
B26: EQUIPMENT ON SITE
B27: Equipment | C27: Owned / Rented | D27: Op Hrs | E27: Idle Hrs | F27: Notes
B34: EQUIP TOTALS | D34: =SUM(D28:D33) | E34: =SUM(E28:E33)
B36: MATERIALS DELIVERED / INSTALLED
B37: Material | C37: Supplier | D37: Qty Delivered | E37: Qty Installed | F37: Location
B45: WORK PERFORMED (NARRATIVE)
B51: CONDITIONS AFFECTING WORK
B52: Differing site conditions
B53: Missing GC trade / access
B54: Utility / power issue
B55: Inspection / AHJ
B56: Idle crew hours due to conditions (#)
B58: DIRECTIVES / RFIs / T&M TICKETS
B59: Type | C59: Originator | D59: Description | E59: Status | F59: Notes
B66: SAFETY
B67: Toolbox topic
B68: Near-miss (count) | C68: 0
B69: First aid only (count) | C69: 0
B70: Recordable incident (count) | C70: 0
B71: OSHA visit | C71: No
B72: PPE audit notes
B74: PHOTO LOG
B75: File / Frame | C75: Time | D75: Location | E75: Description | F75: Notes
B85: SIGNATURES
B86: Foreman:
B87: GC Field Rep (countersig):
A200: Anchor:CrewST | B200: =D24
A201: Anchor:CrewOT | B201: =E24
...

Sheet Day 13
B1: DAILY FIELD REPORT — Day 13
B2: DFR #: | D2: Date: | E2: =IF(FirstDay="","",FirstDay+12) | F2: Project: =ProjectName
B3: Foreman: | C3: =Foreman | D3: Sub: | E3: =SubName
B5: WEATHER
B6: AM Temp (°F) / Conditions
B7: PM Temp (°F) / Conditions
B8: Wind / Visibility
B9: Impact on Work (None / Minor / Hours lost #)
B10: Idle Hours Lost to Weather | C10: 0
B12: CREW ON SITE
B13: Name | C13: Classification | D13: ST Hrs | E13: OT Hrs | F13: Task / Location
B24: CREW TOTALS | D24: =SUM(D14:D23) | E24: =SUM(E14:E23)
B26: EQUIPMENT ON SITE
B27: Equipment | C27: Owned / Rented | D27: Op Hrs | E27: Idle Hrs | F27: Notes
B34: EQUIP TOTALS | D34: =SUM(D28:D33) | E34: =SUM(E28:E33)
B36: MATERIALS DELIVERED / INSTALLED
B37: Material | C37: Supplier | D37: Qty Delivered | E37: Qty Installed | F37: Location
B45: WORK PERFORMED (NARRATIVE)
B51: CONDITIONS AFFECTING WORK
B52: Differing site conditions
B53: Missing GC trade / access
B54: Utility / power issue
B55: Inspection / AHJ
B56: Idle crew hours due to conditions (#)
B58: DIRECTIVES / RFIs / T&M TICKETS
B59: Type | C59: Originator | D59: Description | E59: Status | F59: Notes
B66: SAFETY
B67: Toolbox topic
B68: Near-miss (count) | C68: 0
B69: First aid only (count) | C69: 0
B70: Recordable incident (count) | C70: 0
B71: OSHA visit | C71: No
B72: PPE audit notes
B74: PHOTO LOG
B75: File / Frame | C75: Time | D75: Location | E75: Description | F75: Notes
B85: SIGNATURES
B86: Foreman:
B87: GC Field Rep (countersig):
A200: Anchor:CrewST | B200: =D24
A201: Anchor:CrewOT | B201: =E24
...

Sheet Day 14
B1: DAILY FIELD REPORT — Day 14
B2: DFR #: | D2: Date: | E2: =IF(FirstDay="","",FirstDay+13) | F2: Project: =ProjectName
B3: Foreman: | C3: =Foreman | D3: Sub: | E3: =SubName
B5: WEATHER
B6: AM Temp (°F) / Conditions
B7: PM Temp (°F) / Conditions
B8: Wind / Visibility
B9: Impact on Work (None / Minor / Hours lost #)
B10: Idle Hours Lost to Weather | C10: 0
B12: CREW ON SITE
B13: Name | C13: Classification | D13: ST Hrs | E13: OT Hrs | F13: Task / Location
B24: CREW TOTALS | D24: =SUM(D14:D23) | E24: =SUM(E14:E23)
B26: EQUIPMENT ON SITE
B27: Equipment | C27: Owned / Rented | D27: Op Hrs | E27: Idle Hrs | F27: Notes
B34: EQUIP TOTALS | D34: =SUM(D28:D33) | E34: =SUM(E28:E33)
B36: MATERIALS DELIVERED / INSTALLED
B37: Material | C37: Supplier | D37: Qty Delivered | E37: Qty Installed | F37: Location
B45: WORK PERFORMED (NARRATIVE)
B51: CONDITIONS AFFECTING WORK
B52: Differing site conditions
B53: Missing GC trade / access
B54: Utility / power issue
B55: Inspection / AHJ
B56: Idle crew hours due to conditions (#)
B58: DIRECTIVES / RFIs / T&M TICKETS
B59: Type | C59: Originator | D59: Description | E59: Status | F59: Notes
B66: SAFETY
B67: Toolbox topic
B68: Near-miss (count) | C68: 0
B69: First aid only (count) | C69: 0
B70: Recordable incident (count) | C70: 0
B71: OSHA visit | C71: No
B72: PPE audit notes
B74: PHOTO LOG
B75: File / Frame | C75: Time | D75: Location | E75: Description | F75: Notes
B85: SIGNATURES
B86: Foreman:
B87: GC Field Rep (countersig):
A200: Anchor:CrewST | B200: =D24
A201: Anchor:CrewOT | B201: =E24
...

Sheet Day 15
B1: DAILY FIELD REPORT — Day 15
B2: DFR #: | D2: Date: | E2: =IF(FirstDay="","",FirstDay+14) | F2: Project: =ProjectName
B3: Foreman: | C3: =Foreman | D3: Sub: | E3: =SubName
B5: WEATHER
B6: AM Temp (°F) / Conditions
B7: PM Temp (°F) / Conditions
B8: Wind / Visibility
B9: Impact on Work (None / Minor / Hours lost #)
B10: Idle Hours Lost to Weather | C10: 0
B12: CREW ON SITE
B13: Name | C13: Classification | D13: ST Hrs | E13: OT Hrs | F13: Task / Location
B24: CREW TOTALS | D24: =SUM(D14:D23) | E24: =SUM(E14:E23)
B26: EQUIPMENT ON SITE
B27: Equipment | C27: Owned / Rented | D27: Op Hrs | E27: Idle Hrs | F27: Notes
B34: EQUIP TOTALS | D34: =SUM(D28:D33) | E34: =SUM(E28:E33)
B36: MATERIALS DELIVERED / INSTALLED
B37: Material | C37: Supplier | D37: Qty Delivered | E37: Qty Installed | F37: Location
B45: WORK PERFORMED (NARRATIVE)
B51: CONDITIONS AFFECTING WORK
B52: Differing site conditions
B53: Missing GC trade / access
B54: Utility / power issue
B55: Inspection / AHJ
B56: Idle crew hours due to conditions (#)
B58: DIRECTIVES / RFIs / T&M TICKETS
B59: Type | C59: Originator | D59: Description | E59: Status | F59: Notes
B66: SAFETY
B67: Toolbox topic
B68: Near-miss (count) | C68: 0
B69: First aid only (count) | C69: 0
B70: Recordable incident (count) | C70: 0
B71: OSHA visit | C71: No
B72: PPE audit notes
B74: PHOTO LOG
B75: File / Frame | C75: Time | D75: Location | E75: Description | F75: Notes
B85: SIGNATURES
B86: Foreman:
B87: GC Field Rep (countersig):
A200: Anchor:CrewST | B200: =D24
A201: Anchor:CrewOT | B201: =E24
...

Sheet Day 16
B1: DAILY FIELD REPORT — Day 16
B2: DFR #: | D2: Date: | E2: =IF(FirstDay="","",FirstDay+15) | F2: Project: =ProjectName
B3: Foreman: | C3: =Foreman | D3: Sub: | E3: =SubName
B5: WEATHER
B6: AM Temp (°F) / Conditions
B7: PM Temp (°F) / Conditions
B8: Wind / Visibility
B9: Impact on Work (None / Minor / Hours lost #)
B10: Idle Hours Lost to Weather | C10: 0
B12: CREW ON SITE
B13: Name | C13: Classification | D13: ST Hrs | E13: OT Hrs | F13: Task / Location
B24: CREW TOTALS | D24: =SUM(D14:D23) | E24: =SUM(E14:E23)
B26: EQUIPMENT ON SITE
B27: Equipment | C27: Owned / Rented | D27: Op Hrs | E27: Idle Hrs | F27: Notes
B34: EQUIP TOTALS | D34: =SUM(D28:D33) | E34: =SUM(E28:E33)
B36: MATERIALS DELIVERED / INSTALLED
B37: Material | C37: Supplier | D37: Qty Delivered | E37: Qty Installed | F37: Location
B45: WORK PERFORMED (NARRATIVE)
B51: CONDITIONS AFFECTING WORK
B52: Differing site conditions
B53: Missing GC trade / access
B54: Utility / power issue
B55: Inspection / AHJ
B56: Idle crew hours due to conditions (#)
B58: DIRECTIVES / RFIs / T&M TICKETS
B59: Type | C59: Originator | D59: Description | E59: Status | F59: Notes
B66: SAFETY
B67: Toolbox topic
B68: Near-miss (count) | C68: 0
B69: First aid only (count) | C69: 0
B70: Recordable incident (count) | C70: 0
B71: OSHA visit | C71: No
B72: PPE audit notes
B74: PHOTO LOG
B75: File / Frame | C75: Time | D75: Location | E75: Description | F75: Notes
B85: SIGNATURES
B86: Foreman:
B87: GC Field Rep (countersig):
A200: Anchor:CrewST | B200: =D24
A201: Anchor:CrewOT | B201: =E24
...

Sheet Day 17
B1: DAILY FIELD REPORT — Day 17
B2: DFR #: | D2: Date: | E2: =IF(FirstDay="","",FirstDay+16) | F2: Project: =ProjectName
B3: Foreman: | C3: =Foreman | D3: Sub: | E3: =SubName
B5: WEATHER
B6: AM Temp (°F) / Conditions
B7: PM Temp (°F) / Conditions
B8: Wind / Visibility
B9: Impact on Work (None / Minor / Hours lost #)
B10: Idle Hours Lost to Weather | C10: 0
B12: CREW ON SITE
B13: Name | C13: Classification | D13: ST Hrs | E13: OT Hrs | F13: Task / Location
B24: CREW TOTALS | D24: =SUM(D14:D23) | E24: =SUM(E14:E23)
B26: EQUIPMENT ON SITE
B27: Equipment | C27: Owned / Rented | D27: Op Hrs | E27: Idle Hrs | F27: Notes
B34: EQUIP TOTALS | D34: =SUM(D28:D33) | E34: =SUM(E28:E33)
B36: MATERIALS DELIVERED / INSTALLED
B37: Material | C37: Supplier | D37: Qty Delivered | E37: Qty Installed | F37: Location
B45: WORK PERFORMED (NARRATIVE)
B51: CONDITIONS AFFECTING WORK
B52: Differing site conditions
B53: Missing GC trade / access
B54: Utility / power issue
B55: Inspection / AHJ
B56: Idle crew hours due to conditions (#)
B58: DIRECTIVES / RFIs / T&M TICKETS
B59: Type | C59: Originator | D59: Description | E59: Status | F59: Notes
B66: SAFETY
B67: Toolbox topic
B68: Near-miss (count) | C68: 0
B69: First aid only (count) | C69: 0
B70: Recordable incident (count) | C70: 0
B71: OSHA visit | C71: No
B72: PPE audit notes
B74: PHOTO LOG
B75: File / Frame | C75: Time | D75: Location | E75: Description | F75: Notes
B85: SIGNATURES
B86: Foreman:
B87: GC Field Rep (countersig):
A200: Anchor:CrewST | B200: =D24
A201: Anchor:CrewOT | B201: =E24
...

Sheet Day 18
B1: DAILY FIELD REPORT — Day 18
B2: DFR #: | D2: Date: | E2: =IF(FirstDay="","",FirstDay+17) | F2: Project: =ProjectName
B3: Foreman: | C3: =Foreman | D3: Sub: | E3: =SubName
B5: WEATHER
B6: AM Temp (°F) / Conditions
B7: PM Temp (°F) / Conditions
B8: Wind / Visibility
B9: Impact on Work (None / Minor / Hours lost #)
B10: Idle Hours Lost to Weather | C10: 0
B12: CREW ON SITE
B13: Name | C13: Classification | D13: ST Hrs | E13: OT Hrs | F13: Task / Location
B24: CREW TOTALS | D24: =SUM(D14:D23) | E24: =SUM(E14:E23)
B26: EQUIPMENT ON SITE
B27: Equipment | C27: Owned / Rented | D27: Op Hrs | E27: Idle Hrs | F27: Notes
B34: EQUIP TOTALS | D34: =SUM(D28:D33) | E34: =SUM(E28:E33)
B36: MATERIALS DELIVERED / INSTALLED
B37: Material | C37: Supplier | D37: Qty Delivered | E37: Qty Installed | F37: Location
B45: WORK PERFORMED (NARRATIVE)
B51: CONDITIONS AFFECTING WORK
B52: Differing site conditions
B53: Missing GC trade / access
B54: Utility / power issue
B55: Inspection / AHJ
B56: Idle crew hours due to conditions (#)
B58: DIRECTIVES / RFIs / T&M TICKETS
B59: Type | C59: Originator | D59: Description | E59: Status | F59: Notes
B66: SAFETY
B67: Toolbox topic
B68: Near-miss (count) | C68: 0
B69: First aid only (count) | C69: 0
B70: Recordable incident (count) | C70: 0
B71: OSHA visit | C71: No
B72: PPE audit notes
B74: PHOTO LOG
B75: File / Frame | C75: Time | D75: Location | E75: Description | F75: Notes
B85: SIGNATURES
B86: Foreman:
B87: GC Field Rep (countersig):
A200: Anchor:CrewST | B200: =D24
A201: Anchor:CrewOT | B201: =E24
...

Sheet Day 19
B1: DAILY FIELD REPORT — Day 19
B2: DFR #: | D2: Date: | E2: =IF(FirstDay="","",FirstDay+18) | F2: Project: =ProjectName
B3: Foreman: | C3: =Foreman | D3: Sub: | E3: =SubName
B5: WEATHER
B6: AM Temp (°F) / Conditions
B7: PM Temp (°F) / Conditions
B8: Wind / Visibility
B9: Impact on Work (None / Minor / Hours lost #)
B10: Idle Hours Lost to Weather | C10: 0
B12: CREW ON SITE
B13: Name | C13: Classification | D13: ST Hrs | E13: OT Hrs | F13: Task / Location
B24: CREW TOTALS | D24: =SUM(D14:D23) | E24: =SUM(E14:E23)
B26: EQUIPMENT ON SITE
B27: Equipment | C27: Owned / Rented | D27: Op Hrs | E27: Idle Hrs | F27: Notes
B34: EQUIP TOTALS | D34: =SUM(D28:D33) | E34: =SUM(E28:E33)
B36: MATERIALS DELIVERED / INSTALLED
B37: Material | C37: Supplier | D37: Qty Delivered | E37: Qty Installed | F37: Location
B45: WORK PERFORMED (NARRATIVE)
B51: CONDITIONS AFFECTING WORK
B52: Differing site conditions
B53: Missing GC trade / access
B54: Utility / power issue
B55: Inspection / AHJ
B56: Idle crew hours due to conditions (#)
B58: DIRECTIVES / RFIs / T&M TICKETS
B59: Type | C59: Originator | D59: Description | E59: Status | F59: Notes
B66: SAFETY
B67: Toolbox topic
B68: Near-miss (count) | C68: 0
B69: First aid only (count) | C69: 0
B70: Recordable incident (count) | C70: 0
B71: OSHA visit | C71: No
B72: PPE audit notes
B74: PHOTO LOG
B75: File / Frame | C75: Time | D75: Location | E75: Description | F75: Notes
B85: SIGNATURES
B86: Foreman:
B87: GC Field Rep (countersig):
A200: Anchor:CrewST | B200: =D24
A201: Anchor:CrewOT | B201: =E24
...

Sheet Day 20
B1: DAILY FIELD REPORT — Day 20
B2: DFR #: | D2: Date: | E2: =IF(FirstDay="","",FirstDay+19) | F2: Project: =ProjectName
B3: Foreman: | C3: =Foreman | D3: Sub: | E3: =SubName
B5: WEATHER
B6: AM Temp (°F) / Conditions
B7: PM Temp (°F) / Conditions
B8: Wind / Visibility
B9: Impact on Work (None / Minor / Hours lost #)
B10: Idle Hours Lost to Weather | C10: 0
B12: CREW ON SITE
B13: Name | C13: Classification | D13: ST Hrs | E13: OT Hrs | F13: Task / Location
B24: CREW TOTALS | D24: =SUM(D14:D23) | E24: =SUM(E14:E23)
B26: EQUIPMENT ON SITE
B27: Equipment | C27: Owned / Rented | D27: Op Hrs | E27: Idle Hrs | F27: Notes
B34: EQUIP TOTALS | D34: =SUM(D28:D33) | E34: =SUM(E28:E33)
B36: MATERIALS DELIVERED / INSTALLED
B37: Material | C37: Supplier | D37: Qty Delivered | E37: Qty Installed | F37: Location
B45: WORK PERFORMED (NARRATIVE)
B51: CONDITIONS AFFECTING WORK
B52: Differing site conditions
B53: Missing GC trade / access
B54: Utility / power issue
B55: Inspection / AHJ
B56: Idle crew hours due to conditions (#)
B58: DIRECTIVES / RFIs / T&M TICKETS
B59: Type | C59: Originator | D59: Description | E59: Status | F59: Notes
B66: SAFETY
B67: Toolbox topic
B68: Near-miss (count) | C68: 0
B69: First aid only (count) | C69: 0
B70: Recordable incident (count) | C70: 0
B71: OSHA visit | C71: No
B72: PPE audit notes
B74: PHOTO LOG
B75: File / Frame | C75: Time | D75: Location | E75: Description | F75: Notes
B85: SIGNATURES
B86: Foreman:
B87: GC Field Rep (countersig):
A200: Anchor:CrewST | B200: =D24
A201: Anchor:CrewOT | B201: =E24
...

Sheet Day 21
B1: DAILY FIELD REPORT — Day 21
B2: DFR #: | D2: Date: | E2: =IF(FirstDay="","",FirstDay+20) | F2: Project: =ProjectName
B3: Foreman: | C3: =Foreman | D3: Sub: | E3: =SubName
B5: WEATHER
B6: AM Temp (°F) / Conditions
B7: PM Temp (°F) / Conditions
B8: Wind / Visibility
B9: Impact on Work (None / Minor / Hours lost #)
B10: Idle Hours Lost to Weather | C10: 0
B12: CREW ON SITE
B13: Name | C13: Classification | D13: ST Hrs | E13: OT Hrs | F13: Task / Location
B24: CREW TOTALS | D24: =SUM(D14:D23) | E24: =SUM(E14:E23)
B26: EQUIPMENT ON SITE
B27: Equipment | C27: Owned / Rented | D27: Op Hrs | E27: Idle Hrs | F27: Notes
B34: EQUIP TOTALS | D34: =SUM(D28:D33) | E34: =SUM(E28:E33)
B36: MATERIALS DELIVERED / INSTALLED
B37: Material | C37: Supplier | D37: Qty Delivered | E37: Qty Installed | F37: Location
B45: WORK PERFORMED (NARRATIVE)
B51: CONDITIONS AFFECTING WORK
B52: Differing site conditions
B53: Missing GC trade / access
B54: Utility / power issue
B55: Inspection / AHJ
B56: Idle crew hours due to conditions (#)
B58: DIRECTIVES / RFIs / T&M TICKETS
B59: Type | C59: Originator | D59: Description | E59: Status | F59: Notes
B66: SAFETY
B67: Toolbox topic
B68: Near-miss (count) | C68: 0
B69: First aid only (count) | C69: 0
B70: Recordable incident (count) | C70: 0
B71: OSHA visit | C71: No
B72: PPE audit notes
B74: PHOTO LOG
B75: File / Frame | C75: Time | D75: Location | E75: Description | F75: Notes
B85: SIGNATURES
B86: Foreman:
B87: GC Field Rep (countersig):
A200: Anchor:CrewST | B200: =D24
A201: Anchor:CrewOT | B201: =E24
...

Sheet Day 22
B1: DAILY FIELD REPORT — Day 22
B2: DFR #: | D2: Date: | E2: =IF(FirstDay="","",FirstDay+21) | F2: Project: =ProjectName
B3: Foreman: | C3: =Foreman | D3: Sub: | E3: =SubName
B5: WEATHER
B6: AM Temp (°F) / Conditions
B7: PM Temp (°F) / Conditions
B8: Wind / Visibility
B9: Impact on Work (None / Minor / Hours lost #)
B10: Idle Hours Lost to Weather | C10: 0
B12: CREW ON SITE
B13: Name | C13: Classification | D13: ST Hrs | E13: OT Hrs | F13: Task / Location
B24: CREW TOTALS | D24: =SUM(D14:D23) | E24: =SUM(E14:E23)
B26: EQUIPMENT ON SITE
B27: Equipment | C27: Owned / Rented | D27: Op Hrs | E27: Idle Hrs | F27: Notes
B34: EQUIP TOTALS | D34: =SUM(D28:D33) | E34: =SUM(E28:E33)
B36: MATERIALS DELIVERED / INSTALLED
B37: Material | C37: Supplier | D37: Qty Delivered | E37: Qty Installed | F37: Location
B45: WORK PERFORMED (NARRATIVE)
B51: CONDITIONS AFFECTING WORK
B52: Differing site conditions
B53: Missing GC trade / access
B54: Utility / power issue
B55: Inspection / AHJ
B56: Idle crew hours due to conditions (#)
B58: DIRECTIVES / RFIs / T&M TICKETS
B59: Type | C59: Originator | D59: Description | E59: Status | F59: Notes
B66: SAFETY
B67: Toolbox topic
B68: Near-miss (count) | C68: 0
B69: First aid only (count) | C69: 0
B70: Recordable incident (count) | C70: 0
B71: OSHA visit | C71: No
B72: PPE audit notes
B74: PHOTO LOG
B75: File / Frame | C75: Time | D75: Location | E75: Description | F75: Notes
B85: SIGNATURES
B86: Foreman:
B87: GC Field Rep (countersig):
A200: Anchor:CrewST | B200: =D24
A201: Anchor:CrewOT | B201: =E24
...

Sheet Day 23
B1: DAILY FIELD REPORT — Day 23
B2: DFR #: | D2: Date: | E2: =IF(FirstDay="","",FirstDay+22) | F2: Project: =ProjectName
B3: Foreman: | C3: =Foreman | D3: Sub: | E3: =SubName
B5: WEATHER
B6: AM Temp (°F) / Conditions
B7: PM Temp (°F) / Conditions
B8: Wind / Visibility
B9: Impact on Work (None / Minor / Hours lost #)
B10: Idle Hours Lost to Weather | C10: 0
B12: CREW ON SITE
B13: Name | C13: Classification | D13: ST Hrs | E13: OT Hrs | F13: Task / Location
B24: CREW TOTALS | D24: =SUM(D14:D23) | E24: =SUM(E14:E23)
B26: EQUIPMENT ON SITE
B27: Equipment | C27: Owned / Rented | D27: Op Hrs | E27: Idle Hrs | F27: Notes
B34: EQUIP TOTALS | D34: =SUM(D28:D33) | E34: =SUM(E28:E33)
B36: MATERIALS DELIVERED / INSTALLED
B37: Material | C37: Supplier | D37: Qty Delivered | E37: Qty Installed | F37: Location
B45: WORK PERFORMED (NARRATIVE)
B51: CONDITIONS AFFECTING WORK
B52: Differing site conditions
B53: Missing GC trade / access
B54: Utility / power issue
B55: Inspection / AHJ
B56: Idle crew hours due to conditions (#)
B58: DIRECTIVES / RFIs / T&M TICKETS
B59: Type | C59: Originator | D59: Description | E59: Status | F59: Notes
B66: SAFETY
B67: Toolbox topic
B68: Near-miss (count) | C68: 0
B69: First aid only (count) | C69: 0
B70: Recordable incident (count) | C70: 0
B71: OSHA visit | C71: No
B72: PPE audit notes
B74: PHOTO LOG
B75: File / Frame | C75: Time | D75: Location | E75: Description | F75: Notes
B85: SIGNATURES
B86: Foreman:
B87: GC Field Rep (countersig):
A200: Anchor:CrewST | B200: =D24
A201: Anchor:CrewOT | B201: =E24
...

Sheet Day 24
B1: DAILY FIELD REPORT — Day 24
B2: DFR #: | D2: Date: | E2: =IF(FirstDay="","",FirstDay+23) | F2: Project: =ProjectName
B3: Foreman: | C3: =Foreman | D3: Sub: | E3: =SubName
B5: WEATHER
B6: AM Temp (°F) / Conditions
B7: PM Temp (°F) / Conditions
B8: Wind / Visibility
B9: Impact on Work (None / Minor / Hours lost #)
B10: Idle Hours Lost to Weather | C10: 0
B12: CREW ON SITE
B13: Name | C13: Classification | D13: ST Hrs | E13: OT Hrs | F13: Task / Location
B24: CREW TOTALS | D24: =SUM(D14:D23) | E24: =SUM(E14:E23)
B26: EQUIPMENT ON SITE
B27: Equipment | C27: Owned / Rented | D27: Op Hrs | E27: Idle Hrs | F27: Notes
B34: EQUIP TOTALS | D34: =SUM(D28:D33) | E34: =SUM(E28:E33)
B36: MATERIALS DELIVERED / INSTALLED
B37: Material | C37: Supplier | D37: Qty Delivered | E37: Qty Installed | F37: Location
B45: WORK PERFORMED (NARRATIVE)
B51: CONDITIONS AFFECTING WORK
B52: Differing site conditions
B53: Missing GC trade / access
B54: Utility / power issue
B55: Inspection / AHJ
B56: Idle crew hours due to conditions (#)
B58: DIRECTIVES / RFIs / T&M TICKETS
B59: Type | C59: Originator | D59: Description | E59: Status | F59: Notes
B66: SAFETY
B67: Toolbox topic
B68: Near-miss (count) | C68: 0
B69: First aid only (count) | C69: 0
B70: Recordable incident (count) | C70: 0
B71: OSHA visit | C71: No
B72: PPE audit notes
B74: PHOTO LOG
B75: File / Frame | C75: Time | D75: Location | E75: Description | F75: Notes
B85: SIGNATURES
B86: Foreman:
B87: GC Field Rep (countersig):
A200: Anchor:CrewST | B200: =D24
A201: Anchor:CrewOT | B201: =E24
...

Sheet Day 25
B1: DAILY FIELD REPORT — Day 25
B2: DFR #: | D2: Date: | E2: =IF(FirstDay="","",FirstDay+24) | F2: Project: =ProjectName
B3: Foreman: | C3: =Foreman | D3: Sub: | E3: =SubName
B5: WEATHER
B6: AM Temp (°F) / Conditions
B7: PM Temp (°F) / Conditions
B8: Wind / Visibility
B9: Impact on Work (None / Minor / Hours lost #)
B10: Idle Hours Lost to Weather | C10: 0
B12: CREW ON SITE
B13: Name | C13: Classification | D13: ST Hrs | E13: OT Hrs | F13: Task / Location
B24: CREW TOTALS | D24: =SUM(D14:D23) | E24: =SUM(E14:E23)
B26: EQUIPMENT ON SITE
B27: Equipment | C27: Owned / Rented | D27: Op Hrs | E27: Idle Hrs | F27: Notes
B34: EQUIP TOTALS | D34: =SUM(D28:D33) | E34: =SUM(E28:E33)
B36: MATERIALS DELIVERED / INSTALLED
B37: Material | C37: Supplier | D37: Qty Delivered | E37: Qty Installed | F37: Location
B45: WORK PERFORMED (NARRATIVE)
B51: CONDITIONS AFFECTING WORK
B52: Differing site conditions
B53: Missing GC trade / access
B54: Utility / power issue
B55: Inspection / AHJ
B56: Idle crew hours due to conditions (#)
B58: DIRECTIVES / RFIs / T&M TICKETS
B59: Type | C59: Originator | D59: Description | E59: Status | F59: Notes
B66: SAFETY
B67: Toolbox topic
B68: Near-miss (count) | C68: 0
B69: First aid only (count) | C69: 0
B70: Recordable incident (count) | C70: 0
B71: OSHA visit | C71: No
B72: PPE audit notes
B74: PHOTO LOG
B75: File / Frame | C75: Time | D75: Location | E75: Description | F75: Notes
B85: SIGNATURES
B86: Foreman:
B87: GC Field Rep (countersig):
A200: Anchor:CrewST | B200: =D24
A201: Anchor:CrewOT | B201: =E24
...

Sheet Day 26
B1: DAILY FIELD REPORT — Day 26
B2: DFR #: | D2: Date: | E2: =IF(FirstDay="","",FirstDay+25) | F2: Project: =ProjectName
B3: Foreman: | C3: =Foreman | D3: Sub: | E3: =SubName
B5: WEATHER
B6: AM Temp (°F) / Conditions
B7: PM Temp (°F) / Conditions
B8: Wind / Visibility
B9: Impact on Work (None / Minor / Hours lost #)
B10: Idle Hours Lost to Weather | C10: 0
B12: CREW ON SITE
B13: Name | C13: Classification | D13: ST Hrs | E13: OT Hrs | F13: Task / Location
B24: CREW TOTALS | D24: =SUM(D14:D23) | E24: =SUM(E14:E23)
B26: EQUIPMENT ON SITE
B27: Equipment | C27: Owned / Rented | D27: Op Hrs | E27: Idle Hrs | F27: Notes
B34: EQUIP TOTALS | D34: =SUM(D28:D33) | E34: =SUM(E28:E33)
B36: MATERIALS DELIVERED / INSTALLED
B37: Material | C37: Supplier | D37: Qty Delivered | E37: Qty Installed | F37: Location
B45: WORK PERFORMED (NARRATIVE)
B51: CONDITIONS AFFECTING WORK
B52: Differing site conditions
B53: Missing GC trade / access
B54: Utility / power issue
B55: Inspection / AHJ
B56: Idle crew hours due to conditions (#)
B58: DIRECTIVES / RFIs / T&M TICKETS
B59: Type | C59: Originator | D59: Description | E59: Status | F59: Notes
B66: SAFETY
B67: Toolbox topic
B68: Near-miss (count) | C68: 0
B69: First aid only (count) | C69: 0
B70: Recordable incident (count) | C70: 0
B71: OSHA visit | C71: No
B72: PPE audit notes
B74: PHOTO LOG
B75: File / Frame | C75: Time | D75: Location | E75: Description | F75: Notes
B85: SIGNATURES
B86: Foreman:
B87: GC Field Rep (countersig):
A200: Anchor:CrewST | B200: =D24
A201: Anchor:CrewOT | B201: =E24
...

Sheet Day 27
B1: DAILY FIELD REPORT — Day 27
B2: DFR #: | D2: Date: | E2: =IF(FirstDay="","",FirstDay+26) | F2: Project: =ProjectName
B3: Foreman: | C3: =Foreman | D3: Sub: | E3: =SubName
B5: WEATHER
B6: AM Temp (°F) / Conditions
B7: PM Temp (°F) / Conditions
B8: Wind / Visibility
B9: Impact on Work (None / Minor / Hours lost #)
B10: Idle Hours Lost to Weather | C10: 0
B12: CREW ON SITE
B13: Name | C13: Classification | D13: ST Hrs | E13: OT Hrs | F13: Task / Location
B24: CREW TOTALS | D24: =SUM(D14:D23) | E24: =SUM(E14:E23)
B26: EQUIPMENT ON SITE
B27: Equipment | C27: Owned / Rented | D27: Op Hrs | E27: Idle Hrs | F27: Notes
B34: EQUIP TOTALS | D34: =SUM(D28:D33) | E34: =SUM(E28:E33)
B36: MATERIALS DELIVERED / INSTALLED
B37: Material | C37: Supplier | D37: Qty Delivered | E37: Qty Installed | F37: Location
B45: WORK PERFORMED (NARRATIVE)
B51: CONDITIONS AFFECTING WORK
B52: Differing site conditions
B53: Missing GC trade / access
B54: Utility / power issue
B55: Inspection / AHJ
B56: Idle crew hours due to conditions (#)
B58: DIRECTIVES / RFIs / T&M TICKETS
B59: Type | C59: Originator | D59: Description | E59: Status | F59: Notes
B66: SAFETY
B67: Toolbox topic
B68: Near-miss (count) | C68: 0
B69: First aid only (count) | C69: 0
B70: Recordable incident (count) | C70: 0
B71: OSHA visit | C71: No
B72: PPE audit notes
B74: PHOTO LOG
B75: File / Frame | C75: Time | D75: Location | E75: Description | F75: Notes
B85: SIGNATURES
B86: Foreman:
B87: GC Field Rep (countersig):
A200: Anchor:CrewST | B200: =D24
A201: Anchor:CrewOT | B201: =E24
...

Sheet Day 28
B1: DAILY FIELD REPORT — Day 28
B2: DFR #: | D2: Date: | E2: =IF(FirstDay="","",FirstDay+27) | F2: Project: =ProjectName
B3: Foreman: | C3: =Foreman | D3: Sub: | E3: =SubName
B5: WEATHER
B6: AM Temp (°F) / Conditions
B7: PM Temp (°F) / Conditions
B8: Wind / Visibility
B9: Impact on Work (None / Minor / Hours lost #)
B10: Idle Hours Lost to Weather | C10: 0
B12: CREW ON SITE
B13: Name | C13: Classification | D13: ST Hrs | E13: OT Hrs | F13: Task / Location
B24: CREW TOTALS | D24: =SUM(D14:D23) | E24: =SUM(E14:E23)
B26: EQUIPMENT ON SITE
B27: Equipment | C27: Owned / Rented | D27: Op Hrs | E27: Idle Hrs | F27: Notes
B34: EQUIP TOTALS | D34: =SUM(D28:D33) | E34: =SUM(E28:E33)
B36: MATERIALS DELIVERED / INSTALLED
B37: Material | C37: Supplier | D37: Qty Delivered | E37: Qty Installed | F37: Location
B45: WORK PERFORMED (NARRATIVE)
B51: CONDITIONS AFFECTING WORK
B52: Differing site conditions
B53: Missing GC trade / access
B54: Utility / power issue
B55: Inspection / AHJ
B56: Idle crew hours due to conditions (#)
B58: DIRECTIVES / RFIs / T&M TICKETS
B59: Type | C59: Originator | D59: Description | E59: Status | F59: Notes
B66: SAFETY
B67: Toolbox topic
B68: Near-miss (count) | C68: 0
B69: First aid only (count) | C69: 0
B70: Recordable incident (count) | C70: 0
B71: OSHA visit | C71: No
B72: PPE audit notes
B74: PHOTO LOG
B75: File / Frame | C75: Time | D75: Location | E75: Description | F75: Notes
B85: SIGNATURES
B86: Foreman:
B87: GC Field Rep (countersig):
A200: Anchor:CrewST | B200: =D24
A201: Anchor:CrewOT | B201: =E24
...

Sheet Day 29
B1: DAILY FIELD REPORT — Day 29
B2: DFR #: | D2: Date: | E2: =IF(FirstDay="","",FirstDay+28) | F2: Project: =ProjectName
B3: Foreman: | C3: =Foreman | D3: Sub: | E3: =SubName
B5: WEATHER
B6: AM Temp (°F) / Conditions
B7: PM Temp (°F) / Conditions
B8: Wind / Visibility
B9: Impact on Work (None / Minor / Hours lost #)
B10: Idle Hours Lost to Weather | C10: 0
B12: CREW ON SITE
B13: Name | C13: Classification | D13: ST Hrs | E13: OT Hrs | F13: Task / Location
B24: CREW TOTALS | D24: =SUM(D14:D23) | E24: =SUM(E14:E23)
B26: EQUIPMENT ON SITE
B27: Equipment | C27: Owned / Rented | D27: Op Hrs | E27: Idle Hrs | F27: Notes
B34: EQUIP TOTALS | D34: =SUM(D28:D33) | E34: =SUM(E28:E33)
B36: MATERIALS DELIVERED / INSTALLED
B37: Material | C37: Supplier | D37: Qty Delivered | E37: Qty Installed | F37: Location
B45: WORK PERFORMED (NARRATIVE)
B51: CONDITIONS AFFECTING WORK
B52: Differing site conditions
B53: Missing GC trade / access
B54: Utility / power issue
B55: Inspection / AHJ
B56: Idle crew hours due to conditions (#)
B58: DIRECTIVES / RFIs / T&M TICKETS
B59: Type | C59: Originator | D59: Description | E59: Status | F59: Notes
B66: SAFETY
B67: Toolbox topic
B68: Near-miss (count) | C68: 0
B69: First aid only (count) | C69: 0
B70: Recordable incident (count) | C70: 0
B71: OSHA visit | C71: No
B72: PPE audit notes
B74: PHOTO LOG
B75: File / Frame | C75: Time | D75: Location | E75: Description | F75: Notes
B85: SIGNATURES
B86: Foreman:
B87: GC Field Rep (countersig):
A200: Anchor:CrewST | B200: =D24
A201: Anchor:CrewOT | B201: =E24
...

Sheet Day 30
B1: DAILY FIELD REPORT — Day 30
B2: DFR #: | D2: Date: | E2: =IF(FirstDay="","",FirstDay+29) | F2: Project: =ProjectName
B3: Foreman: | C3: =Foreman | D3: Sub: | E3: =SubName
B5: WEATHER
B6: AM Temp (°F) / Conditions
B7: PM Temp (°F) / Conditions
B8: Wind / Visibility
B9: Impact on Work (None / Minor / Hours lost #)
B10: Idle Hours Lost to Weather | C10: 0
B12: CREW ON SITE
B13: Name | C13: Classification | D13: ST Hrs | E13: OT Hrs | F13: Task / Location
B24: CREW TOTALS | D24: =SUM(D14:D23) | E24: =SUM(E14:E23)
B26: EQUIPMENT ON SITE
B27: Equipment | C27: Owned / Rented | D27: Op Hrs | E27: Idle Hrs | F27: Notes
B34: EQUIP TOTALS | D34: =SUM(D28:D33) | E34: =SUM(E28:E33)
B36: MATERIALS DELIVERED / INSTALLED
B37: Material | C37: Supplier | D37: Qty Delivered | E37: Qty Installed | F37: Location
B45: WORK PERFORMED (NARRATIVE)
B51: CONDITIONS AFFECTING WORK
B52: Differing site conditions
B53: Missing GC trade / access
B54: Utility / power issue
B55: Inspection / AHJ
B56: Idle crew hours due to conditions (#)
B58: DIRECTIVES / RFIs / T&M TICKETS
B59: Type | C59: Originator | D59: Description | E59: Status | F59: Notes
B66: SAFETY
B67: Toolbox topic
B68: Near-miss (count) | C68: 0
B69: First aid only (count) | C69: 0
B70: Recordable incident (count) | C70: 0
B71: OSHA visit | C71: No
B72: PPE audit notes
B74: PHOTO LOG
B75: File / Frame | C75: Time | D75: Location | E75: Description | F75: Notes
B85: SIGNATURES
B86: Foreman:
B87: GC Field Rep (countersig):
A200: Anchor:CrewST | B200: =D24
A201: Anchor:CrewOT | B201: =E24
...

Sheet Day 31
B1: DAILY FIELD REPORT — Day 31
B2: DFR #: | D2: Date: | E2: =IF(FirstDay="","",FirstDay+30) | F2: Project: =ProjectName
B3: Foreman: | C3: =Foreman | D3: Sub: | E3: =SubName
B5: WEATHER
B6: AM Temp (°F) / Conditions
B7: PM Temp (°F) / Conditions
B8: Wind / Visibility
B9: Impact on Work (None / Minor / Hours lost #)
B10: Idle Hours Lost to Weather | C10: 0
B12: CREW ON SITE
B13: Name | C13: Classification | D13: ST Hrs | E13: OT Hrs | F13: Task / Location
B24: CREW TOTALS | D24: =SUM(D14:D23) | E24: =SUM(E14:E23)
B26: EQUIPMENT ON SITE
B27: Equipment | C27: Owned / Rented | D27: Op Hrs | E27: Idle Hrs | F27: Notes
B34: EQUIP TOTALS | D34: =SUM(D28:D33) | E34: =SUM(E28:E33)
B36: MATERIALS DELIVERED / INSTALLED
B37: Material | C37: Supplier | D37: Qty Delivered | E37: Qty Installed | F37: Location
B45: WORK PERFORMED (NARRATIVE)
B51: CONDITIONS AFFECTING WORK
B52: Differing site conditions
B53: Missing GC trade / access
B54: Utility / power issue
B55: Inspection / AHJ
B56: Idle crew hours due to conditions (#)
B58: DIRECTIVES / RFIs / T&M TICKETS
B59: Type | C59: Originator | D59: Description | E59: Status | F59: Notes
B66: SAFETY
B67: Toolbox topic
B68: Near-miss (count) | C68: 0
B69: First aid only (count) | C69: 0
B70: Recordable incident (count) | C70: 0
B71: OSHA visit | C71: No
B72: PPE audit notes
B74: PHOTO LOG
B75: File / Frame | C75: Time | D75: Location | E75: Description | F75: Notes
B85: SIGNATURES
B86: Foreman:
B87: GC Field Rep (countersig):
A200: Anchor:CrewST | B200: =D24
A201: Anchor:CrewOT | B201: =E24
...
